Workbook
Name flag1: INDIRECT('VM-tipset 2026 mall'!$AV$204)
Name flag10: INDIRECT('VM-tipset 2026 mall'!#REF!)
Name flag11: INDIRECT('VM-tipset 2026 mall'!#REF!)
Name flag12: INDIRECT('VM-tipset 2026 mall'!#REF!)
Name flag13: INDIRECT('VM-tipset 2026 mall'!#REF!)
Name flag14: INDIRECT('VM-tipset 2026 mall'!#REF!)
Name flag15: INDIRECT('VM-tipset 2026 mall'!#REF!)
Name flag16: INDIRECT('VM-tipset 2026 mall'!#REF!)
Name flag17: INDIRECT('VM-tipset 2026 mall'!#REF!)
Name flag18: INDIRECT('VM-tipset 2026 mall'!#REF!)
Name flag19: INDIRECT('VM-tipset 2026 mall'!#REF!)
Name flag2: INDIRECT('VM-tipset 2026 mall'!$AV$205)
Name flag20: INDIRECT('VM-tipset 2026 mall'!#REF!)
Name flag21: INDIRECT('VM-tipset 2026 mall'!#REF!)
Name flag22: INDIRECT('VM-tipset 2026 mall'!#REF!)
Name flag23: INDIRECT('VM-tipset 2026 mall'!#REF!)
Name flag24: INDIRECT('VM-tipset 2026 mall'!#REF!)
Name flag25: INDIRECT('VM-tipset 2026 mall'!#REF!)
Name flag26: INDIRECT('VM-tipset 2026 mall'!#REF!)
Name flag27: INDIRECT('VM-tipset 2026 mall'!#REF!)
Name flag28: INDIRECT('VM-tipset 2026 mall'!#REF!)
Name flag29: INDIRECT('VM-tipset 2026 mall'!#REF!)
Name flag3: INDIRECT('VM-tipset 2026 mall'!$AV$206)
Name flag30: INDIRECT('VM-tipset 2026 mall'!#REF!)
Name flag31: INDIRECT('VM-tipset 2026 mall'!#REF!)
Name flag32: INDIRECT('VM-tipset 2026 mall'!#REF!)
Name flag4: INDIRECT('VM-tipset 2026 mall'!$AV$207)
Name flag5: INDIRECT('VM-tipset 2026 mall'!$AV$212)
Name flag6: INDIRECT('VM-tipset 2026 mall'!$AV$213)
Name flag7: INDIRECT('VM-tipset 2026 mall'!$AV$214)
Name flag8: INDIRECT('VM-tipset 2026 mall'!#REF!)
Name flag9: INDIRECT('VM-tipset 2026 mall'!#REF!)

Sheet VM-tipset 2026 mall
BD1: Resultatpoäng | BG1: 1X2 | BN1: Tabell poäng | BV1: Mål faktiskt resultat | BY1: Ranking | BZ1: Land | CA1: Ranking | CB1: Land
C2: Ditt spel | AB2: Resultat | BV2: 0
BV3: 1 | BY3: 1 | BZ3: Spanien | CA3: 25 | CB3: Turkiet
C4: Ditt namn: | BV4: 2 | BY4: 2 | BZ4: Argentina | CA4: 26 | CB4: Skottland
AB5: - När turneringen har startat fyller du i det rätta resultatet. På så vis rättar du din kupong för varje spelad match. Mest för du själv ska ha koll på dina poäng. Efter varje spelad omgång uppdateras dina poäng på länken nedan "Poängställning" - Annan information kommer uppdateras på Facebook i gruppen VM-tipset 2026 | BV5: 3 | BY5: 3 | BZ5: Frankrike | CA5: 27 | CB5: Sverige
C6: Din email: | W6: Dina poäng | BV6: 4 | BY6: 4 | BZ6: England | CA6: 28 | CB6: Egypten
BV7: 5 | BY7: 5 | BZ7: Brasilien | CA7: 29 | CB7: Algeriet
C8: Din poäng | G8: =J174 -> 0 | BV8: 6 | BY8: 6 | BZ8: Portugal | CA8: 30 | CB8: Tunisien
W9: Resultatpoäng | X9: 1X2 Poäng | Y9: Tabellpoäng | BV9: 7 | BY9: 7 | BZ9: Nederländerna | CA9: 31 | CB9: Paraguay
C10: << Instruktioner >> | BV10: 8 | BY10: 8 | BZ10: Marocko | CA10: 32 | CB10: Elfenbenskusten
AB11: <<Poängställning - KLICKA HÄR>> | BV11: 9 | BY11: 9 | BZ11: Belgien | CA11: 33 | CB11: Tjeckien
C12: Resultat = 2p | H12: 1X2 = 1p | K12: Sluttabell = 2p/lag | BY12: 10 | BZ12: Tyskland | CA12: 34 | CB12: Bosnien och Hercegovina
A13: Match nr | B13: Grupp A | G13: 1 | H13: X | I13: 2 | K13: Grupp A | L13: S | M13: V | N13: O | O13: F | P13: GM | Q13: IM | R13: M+/- | S13: Poäng | AB13: Grupp A | AG13: 1 | AH13: X | AI13: 2 | AK13: Grupp A | BN13: Tabell poäng | BY13: 11 | BZ13: Kroatien | CA13: 35 | CB13: Saudiarabien
A14: M1 | B14: =BP76 -> Mexiko | D14: ― | F14: =BP77 -> Sydafrika | G14: =IF(C14>E14,1," ") | H14: =IF(C14="","",+IF(C14=E14,1," ")) | I14: =IF(C14<E14,1," ") | J14: 1 | K14: ='Grupp A'!L7 -> Mexiko | L14: ='Grupp A'!M7 -> 0 | M14: ='Grupp A'!N7 -> 0 | N14: ='Grupp A'!O7 -> 0 | O14: ='Grupp A'!P7 -> 0 | P14: ='Grupp A'!Q7 -> 0 | Q14: ='Grupp A'!R7 -> 0 | R14: ='Grupp A'!S7 -> 0 | S14: ='Grupp A'!T7 -> 0 | W14: =IF(AC14="","",AY14) | X14: =IF(AC14="","",BF14) | Y14: =IF(AK14=0,"",BG14) | AA14: =IF(A14=$G$6,">>"," ") | AB14: =B14 -> Mexiko | AD14: ― | AF14: =F14 -> Sydafrika | AG14: =IF(AC14>AE14,1," ") | AH14: =IF(AC14="","",+IF(AC14=AE14,1," ")) | AI14: =IF(AC14<AE14,1," ") | AJ14: 1 | AW14: =IF(C14=AC14,1,0)+IF(AE14=E14,1,0) -> 2 | AX14: --> | AY14: =IF(AW14=2,2,0) -> 2 | AZ14: =AG14+G14 -> #VALUE! | BA14: =AH14+H14 -> #VALUE! | BB14: =AI14+I14 -> #VALUE! | BC14: --> | BD14: =COUNTIF(AZ14:BB14,2) -> 0 | BE14: --> | BF14: =IF(BD14=1,1,0) -> 0 | BG14: =IF(AK14=K14,2,0) -> 0 | BY14: 12 | BZ14: USA | CA14: 36 | CB14: Sydkorea
A15: M2 | B15: =BP78 -> Sydkorea | D15: ― | F15: =BP79 -> Tjeckien | G15: =IF(C15>E15,1," ") | H15: =IF(C15="","",+IF(C15=E15,1," ")) | I15: =IF(C15<E15,1," ") | J15: 2 | K15: ='Grupp A'!L8 -> Sydafrika | L15: ='Grupp A'!M8 -> 0 | M15: ='Grupp A'!N8 -> 0 | N15: ='Grupp A'!O8 -> 0 | O15: ='Grupp A'!P8 -> 0 | P15: ='Grupp A'!Q8 -> 0 | Q15: ='Grupp A'!R8 -> 0 | R15: ='Grupp A'!S8 -> 0 | S15: ='Grupp A'!T8 -> 0 | W15: =IF(AC15="","",AY15) | X15: =IF(AC15="","",BF15) | Y15: =IF(AK15=0,"",BG15) | AA15: =IF(A15=$G$6,">>"," ") | AB15: =B15 -> Sydkorea | AD15: ― | AF15: =F15 -> Tjeckien | AG15: =IF(AC15>AE15,1," ") | AH15: =IF(AC15="","",+IF(AC15=AE15,1," ")) | AI15: =IF(AC15<AE15,1," ") | AJ15: 2 | AW15: =IF(C15=AC15,1,0)+IF(AE15=E15,1,0) -> 2 | AX15: --> | AY15: =IF(AW15=2,2,0) -> 2 | AZ15: =AG15+G15 -> #VALUE! | BA15: =AH15+H15 -> #VALUE! | BB15: =AI15+I15 -> #VALUE! | BC15: --> | BD15: =COUNTIF(AZ15:BB15,2) -> 0 | BE15: --> | BF15: =IF(BD15=1,1,0) -> 0 | BG15: =IF(AK15=K15,2,0) -> 0 | BY15: 13 | BZ15: Mexiko | CA15: 37 | CB15: Qatar
A16: M3 | B16: =BP76 -> Mexiko | D16: ― | F16: =BP78 -> Sydkorea | G16: =IF(C16>E16,1," ") | H16: =IF(C16="","",+IF(C16=E16,1," ")) | I16: =IF(C16<E16,1," ") | J16: 3 | K16: ='Grupp A'!L9 -> Sydkorea | L16: ='Grupp A'!M9 -> 0 | M16: ='Grupp A'!N9 -> 0 | N16: ='Grupp A'!O9 -> 0 | O16: ='Grupp A'!P9 -> 0 | P16: ='Grupp A'!Q9 -> 0 | Q16: ='Grupp A'!R9 -> 0 | R16: ='Grupp A'!S9 -> 0 | S16: ='Grupp A'!T9 -> 0 | W16: =IF(AC16="","",AY16) | X16: =IF(AC16="","",BF16) | Y16: =IF(AK16=0,"",BG16) | AA16: =IF(A16=$G$6,">>"," ") | AB16: =B16 -> Mexiko | AD16: ― | AF16: =F16 -> Sydkorea | AG16: =IF(AC16>AE16,1," ") | AH16: =IF(AC16="","",+IF(AC16=AE16,1," ")) | AI16: =IF(AC16<AE16,1," ") | AJ16: 3 | AW16: =IF(C16=AC16,1,0)+IF(AE16=E16,1,0) -> 2 | AX16: --> | AY16: =IF(AW16=2,2,0) -> 2 | AZ16: =AG16+G16 -> #VALUE! | BA16: =AH16+H16 -> #VALUE! | BB16: =AI16+I16 -> #VALUE! | BC16: --> | BD16: =COUNTIF(AZ16:BB16,2) -> 0 | BE16: --> | BF16: =IF(BD16=1,1,0) -> 0 | BG16: =IF(AK16=K16,2,0) -> 0 | BY16: 14 | BZ16: Uruguay | CA16: 38 | CB16: Ghana
A17: M4 | B17: =BP77 -> Sydafrika | D17: ― | F17: =BP79 -> Tjeckien | G17: =IF(C17>E17,1," ") | H17: =IF(C17="","",+IF(C17=E17,1," ")) | I17: =IF(C17<E17,1," ") | J17: 4 | K17: ='Grupp A'!L10 -> Tjeckien | L17: ='Grupp A'!M10 -> 0 | M17: ='Grupp A'!N10 -> 0 | N17: ='Grupp A'!O10 -> 0 | O17: ='Grupp A'!P10 -> 0 | P17: ='Grupp A'!Q10 -> 0 | Q17: ='Grupp A'!R10 -> 0 | R17: ='Grupp A'!S10 -> 0 | S17: ='Grupp A'!T10 -> 0 | W17: =IF(AC17="","",AY17) | X17: =IF(AC17="","",BF17) | Y17: =IF(AK17=0,"",BG17) | AA17: =IF(A17=$G$6,">>"," ") | AB17: =B17 -> Sydafrika | AD17: ― | AF17: =F17 -> Tjeckien | AG17: =IF(AC17>AE17,1," ") | AH17: =IF(AC17="","",+IF(AC17=AE17,1," ")) | AI17: =IF(AC17<AE17,1," ") | AJ17: 4 | AW17: =IF(C17=AC17,1,0)+IF(AE17=E17,1,0) -> 2 | AX17: --> | AY17: =IF(AW17=2,2,0) -> 2 | AZ17: =AG17+G17 -> #VALUE! | BA17: =AH17+H17 -> #VALUE! | BB17: =AI17+I17 -> #VALUE! | BC17: --> | BD17: =COUNTIF(AZ17:BB17,2) -> 0 | BE17: --> | BF17: =IF(BD17=1,1,0) -> 0 | BG17: =IF(AK17=K17,2,0) -> 0 | BY17: 15 | BZ17: Colombia | CA17: 39 | CB17: Panama
A18: M5 | B18: =BP76 -> Mexiko | D18: ― | F18: =BP79 -> Tjeckien | G18: =IF(C18>E18,1," ") | H18: =IF(C18="","",+IF(C18=E18,1," ")) | I18: =IF(C18<E18,1," ") | W18: =IF(AC18="","",AY18) | X18: =IF(AC18="","",BF18) | AA18: =IF(A18=$G$6,">>"," ") | AB18: =B18 -> Mexiko | AD18: ― | AF18: =F18 -> Tjeckien | AG18: =IF(AC18>AE18,1," ") | AH18: =IF(AC18="","",+IF(AC18=AE18,1," ")) | AI18: =IF(AC18<AE18,1," ") | AW18: =IF(C18=AC18,1,0)+IF(AE18=E18,1,0) -> 2 | AX18: --> | AY18: =IF(AW18=2,2,0) -> 2 | AZ18: =AG18+G18 -> #VALUE! | BA18: =AH18+H18 -> #VALUE! | BB18: =AI18+I18 -> #VALUE! | BC18: --> | BD18: =COUNTIF(AZ18:BB18,2) -> 0 | BE18: --> | BF18: =IF(BD18=1,1,0) -> 0 | BY18: 16 | BZ18: Schweiz | CA18: 40 | CB18: Sydafrika
A19: M6 | B19: =BP77 -> Sydafrika | D19: ― | F19: =BP78 -> Sydkorea | G19: =IF(C19>E19,1," ") | H19: =IF(C19="","",+IF(C19=E19,1," ")) | I19: =IF(C19<E19,1," ") | W19: =IF(AC19="","",AY19) | X19: =IF(AC19="","",BF19) | AA19: =IF(A19=$G$6,">>"," ") | AB19: =B19 -> Sydafrika | AD19: ― | AF19: =F19 -> Sydkorea | AG19: =IF(AC19>AE19,1," ") | AH19: =IF(AC19="","",+IF(AC19=AE19,1," ")) | AI19: =IF(AC19<AE19,1," ") | AW19: =IF(C19=AC19,1,0)+IF(AE19=E19,1,0) -> 2 | AX19: --> | AY19: =IF(AW19=2,2,0) -> 2 | AZ19: =AG19+G19 -> #VALUE! | BA19: =AH19+H19 -> #VALUE! | BB19: =AI19+I19 -> #VALUE! | BC19: --> | BD19: =COUNTIF(AZ19:BB19,2) -> 0 | BE19: --> | BF19: =IF(BD19=1,1,0) -> 0 | BY19: 17 | BZ19: Japan | CA19: 41 | CB19: Irak
W20: =SUM(W14:Y19) -> 0 | X20: av | Y20: Max 26 | BK20: Polen | BY20: 18 | BZ20: Iran | CA20: 42 | CB20: Kap Verde
B21: Grupp B | G21: 1 | H21: X | I21: 2 | K21: Grupp B | L21: S | M21: V | N21: O | O21: F | P21: GM | Q21: IM | R21: M+/- | S21: Poäng | AB21: Grupp B | AG21: 1 | AH21: X | AI21: 2 | AK21: Grupp B | BK21: Portugal | BY21: 19 | BZ21: Senegal | CA21: 43 | CB21: Demokratiska republiken Kongo
A22: M7 | B22: =BP81 -> Kanada | D22: ― | F22: =BP82 -> Bosnien | G22: =IF(C22>E22,1," ") | H22: =IF(C22="","",+IF(C22=E22,1," ")) | I22: =IF(C22<E22,1," ") | J22: 1 | K22: ='Grupp B'!L7 -> Kanada | L22: ='Grupp B'!M7 -> 0 | M22: ='Grupp B'!N7 -> 0 | N22: ='Grupp B'!O7 -> 0 | O22: ='Grupp B'!P7 -> 0 | P22: ='Grupp B'!Q7 -> 0 | Q22: ='Grupp B'!R7 -> 0 | R22: ='Grupp B'!S7 -> 0 | S22: ='Grupp B'!T7 -> 0 | W22: =IF(AC22="","",AY22) | X22: =IF(AC22="","",BF22) | Y22: =IF(AK22=0,"",BG22) | AB22: =B22 -> Kanada | AD22: ― | AF22: =F22 -> Bosnien | AG22: =IF(AC22>AE22,1," ") | AH22: =IF(AC22="","",+IF(AC22=AE22,1," ")) | AI22: =IF(AC22<AE22,1," ") | AJ22: 1 | AW22: =IF(C22=AC22,1,0)+IF(AE22=E22,1,0) -> 2 | AX22: --> | AY22: =IF(AW22=2,2,0) -> 2 | AZ22: =AG22+G22 -> #VALUE! | BA22: =AH22+H22 -> #VALUE! | BB22: =AI22+I22 -> #VALUE! | BC22: --> | BD22: =COUNTIF(AZ22:BB22,2) -> 0 | BE22: --> | BF22: =IF(BD22=1,1,0) -> 0 | BG22: =IF(AK22=K22,2,0) -> 0 | BK22: Qatar | BY22: 20 | BZ22: Danmark | CA22: 44 | CB22: Uzbekistan
A23: M8 | B23: =BP83 -> Qatar | D23: ― | F23: =BP84 -> Schweiz | G23: =IF(C23>E23,1," ") | H23: =IF(C23="","",+IF(C23=E23,1," ")) | I23: =IF(C23<E23,1," ") | J23: 2 | K23: ='Grupp B'!L8 -> Bosnien | L23: ='Grupp B'!M8 -> 0 | M23: ='Grupp B'!N8 -> 0 | N23: ='Grupp B'!O8 -> 0 | O23: ='Grupp B'!P8 -> 0 | P23: ='Grupp B'!Q8 -> 0 | Q23: ='Grupp B'!R8 -> 0 | R23: ='Grupp B'!S8 -> 0 | S23: ='Grupp B'!T8 -> 0 | W23: =IF(AC23="","",AY23) | X23: =IF(AC23="","",BF23) | Y23: =IF(AK23=0,"",BG23) | AB23: =B23 -> Qatar | AD23: ― | AF23: =F23 -> Schweiz | AG23: =IF(AC23>AE23,1," ") | AH23: =IF(AC23="","",+IF(AC23=AE23,1," ")) | AI23: =IF(AC23<AE23,1," ") | AJ23: 2 | AW23: =IF(C23=AC23,1,0)+IF(AE23=E23,1,0) -> 2 | AX23: --> | AY23: =IF(AW23=2,2,0) -> 2 | AZ23: =AG23+G23 -> #VALUE! | BA23: =AH23+H23 -> #VALUE! | BB23: =AI23+I23 -> #VALUE! | BC23: --> | BD23: =COUNTIF(AZ23:BB23,2) -> 0 | BE23: --> | BF23: =IF(BD23=1,1,0) -> 0 | BG23: =IF(AK23=K23,2,0) -> 0 | BK23: Saudiarabien | BY23: 21 | BZ23: Österrike | CA23: 45 | CB23: Kanada
A24: M9 | B24: =BP81 -> Kanada | D24: ― | F24: =BP83 -> Qatar | G24: =IF(C24>E24,1," ") | H24: =IF(C24="","",+IF(C24=E24,1," ")) | I24: =IF(C24<E24,1," ") | J24: 3 | K24: ='Grupp B'!L9 -> Qatar | L24: ='Grupp B'!M9 -> 0 | M24: ='Grupp B'!N9 -> 0 | N24: ='Grupp B'!O9 -> 0 | O24: ='Grupp B'!P9 -> 0 | P24: ='Grupp B'!Q9 -> 0 | Q24: ='Grupp B'!R9 -> 0 | R24: ='Grupp B'!S9 -> 0 | S24: ='Grupp B'!T9 -> 0 | W24: =IF(AC24="","",AY24) | X24: =IF(AC24="","",BF24) | Y24: =IF(AK24=0,"",BG24) | AB24: =B24 -> Kanada | AD24: ― | AF24: =F24 -> Qatar | AG24: =IF(AC24>AE24,1," ") | AH24: =IF(AC24="","",+IF(AC24=AE24,1," ")) | AI24: =IF(AC24<AE24,1," ") | AJ24: 3 | AW24: =IF(C24=AC24,1,0)+IF(AE24=E24,1,0) -> 2 | AX24: --> | AY24: =IF(AW24=2,2,0) -> 2 | AZ24: =AG24+G24 -> #VALUE! | BA24: =AH24+H24 -> #VALUE! | BB24: =AI24+I24 -> #VALUE! | BC24: --> | BD24: =COUNTIF(AZ24:BB24,2) -> 0 | BE24: --> | BF24: =IF(BD24=1,1,0) -> 0 | BG24: =IF(AK24=K24,2,0) -> 0 | BK24: Schweiz | BY24: 22 | BZ24: Australien | CA24: 46 | CB24: Jordanien
A25: M10 | B25: =BP82 -> Bosnien | D25: ― | F25: =BP84 -> Schweiz | G25: =IF(C25>E25,1," ") | H25: =IF(C25="","",+IF(C25=E25,1," ")) | I25: =IF(C25<E25,1," ") | J25: 4 | K25: ='Grupp B'!L10 -> Schweiz | L25: ='Grupp B'!M10 -> 0 | M25: ='Grupp B'!N10 -> 0 | N25: ='Grupp B'!O10 -> 0 | O25: ='Grupp B'!P10 -> 0 | P25: ='Grupp B'!Q10 -> 0 | Q25: ='Grupp B'!R10 -> 0 | R25: ='Grupp B'!S10 -> 0 | S25: ='Grupp B'!T10 -> 0 | W25: =IF(AC25="","",AY25) | X25: =IF(AC25="","",BF25) | Y25: =IF(AK25=0,"",BG25) | AB25: =B25 -> Bosnien | AD25: ― | AF25: =F25 -> Schweiz | AG25: =IF(AC25>AE25,1," ") | AH25: =IF(AC25="","",+IF(AC25=AE25,1," ")) | AI25: =IF(AC25<AE25,1," ") | AJ25: 4 | AW25: =IF(C25=AC25,1,0)+IF(AE25=E25,1,0) -> 2 | AX25: --> | AY25: =IF(AW25=2,2,0) -> 2 | AZ25: =AG25+G25 -> #VALUE! | BA25: =AH25+H25 -> #VALUE! | BB25: =AI25+I25 -> #VALUE! | BC25: --> | BD25: =COUNTIF(AZ25:BB25,2) -> 0 | BE25: --> | BF25: =IF(BD25=1,1,0) -> 0 | BG25: =IF(AK25=K25,2,0) -> 0 | BK25: Senegal | BY25: 23 | BZ25: Ecuador | CA25: 47 | CB25: Haiti
A26: M11 | B26: =BP81 -> Kanada | D26: ― | F26: =BP84 -> Schweiz | G26: =IF(C26>E26,1," ") | H26: =IF(C26="","",+IF(C26=E26,1," ")) | I26: =IF(C26<E26,1," ") | W26: =IF(AC26="","",AY26) | X26: =IF(AC26="","",BF26) | AB26: =B26 -> Kanada | AD26: ― | AF26: =F26 -> Schweiz | AG26: =IF(AC26>AE26,1," ") | AH26: =IF(AC26="","",+IF(AC26=AE26,1," ")) | AI26: =IF(AC26<AE26,1," ") | AW26: =IF(C26=AC26,1,0)+IF(AE26=E26,1,0) -> 2 | AX26: --> | AY26: =IF(AW26=2,2,0) -> 2 | AZ26: =AG26+G26 -> #VALUE! | BA26: =AH26+H26 -> #VALUE! | BB26: =AI26+I26 -> #VALUE! | BC26: --> | BD26: =COUNTIF(AZ26:BB26,2) -> 0 | BE26: --> | BF26: =IF(BD26=1,1,0) -> 0 | BK26: Serbien | BY26: 24 | BZ26: Norge | CA26: 48 | CB26: Curaçao
A27: M12 | B27: =BP82 -> Bosnien | D27: ― | F27: =BP83 -> Qatar | G27: =IF(C27>E27,1," ") | H27: =IF(C27="","",+IF(C27=E27,1," ")) | I27: =IF(C27<E27,1," ") | W27: =IF(AC27="","",AY27) | X27: =IF(AC27="","",BF27) | AB27: =B27 -> Bosnien | AD27: ― | AF27: =F27 -> Qatar | AG27: =IF(AC27>AE27,1," ") | AH27: =IF(AC27="","",+IF(AC27=AE27,1," ")) | AI27: =IF(AC27<AE27,1," ") | AW27: =IF(C27=AC27,1,0)+IF(AE27=E27,1,0) -> 2 | AX27: --> | AY27: =IF(AW27=2,2,0) -> 2 | AZ27: =AG27+G27 -> #VALUE! | BA27: =AH27+H27 -> #VALUE! | BB27: =AI27+I27 -> #VALUE! | BC27: --> | BD27: =COUNTIF(AZ27:BB27,2) -> 0 | BE27: --> | BF27: =IF(BD27=1,1,0) -> 0 | BK27: Spanien
W28: =SUM(W22:Y27) -> 0 | X28: av | Y28: Max 26 | BK28: Sydkorea
B29: Grupp C | G29: 1 | H29: X | I29: 2 | K29: Grupp C | L29: S | M29: V | N29: O | O29: F | P29: GM | Q29: IM | R29: M+/- | S29: Poäng | AB29: Grupp C | AG29: 1 | AH29: X | AI29: 2 | AK29: Grupp C | BK29: Tunisien
A30: M13 | B30: =BP86 -> Brasilien | D30: ― | F30: =BP87 -> Marocko | G30: =IF(C30>E30,1," ") | H30: =IF(C30="","",+IF(C30=E30,1," ")) | I30: =IF(C30<E30,1," ") | J30: 1 | K30: ='Grupp C'!L7 -> Brasilien | L30: ='Grupp C'!M7 -> 0 | M30: ='Grupp C'!N7 -> 0 | N30: ='Grupp C'!O7 -> 0 | O30: ='Grupp C'!P7 -> 0 | P30: ='Grupp C'!Q7 -> 0 | Q30: ='Grupp C'!R7 -> 0 | R30: ='Grupp C'!S7 -> 0 | S30: ='Grupp C'!T7 -> 0 | W30: =IF(AC30="","",AY30) | X30: =IF(AC30="","",BF30) | Y30: =IF(AK30=0,"",BG30) | AB30: =B30 -> Brasilien | AD30: ― | AF30: =F30 -> Marocko | AG30: =IF(AC30>AE30,1," ") | AH30: =IF(AC30="","",+IF(AC30=AE30,1," ")) | AI30: =IF(AC30<AE30,1," ") | AJ30: 1 | AW30: =IF(C30=AC30,1,0)+IF(AE30=E30,1,0) -> 2 | AX30: --> | AY30: =IF(AW30=2,2,0) -> 2 | AZ30: =AG30+G30 -> #VALUE! | BA30: =AH30+H30 -> #VALUE! | BB30: =AI30+I30 -> #VALUE! | BC30: --> | BD30: =COUNTIF(AZ30:BB30,2) -> 0 | BE30: --> | BF30: =IF(BD30=1,1,0) -> 0 | BG30: =IF(AK30=K30,2,0) -> 0 | BK30: Tyskland
A31: M14 | B31: =BP88 -> Haiti | D31: ― | F31: =BP89 -> Skottland | G31: =IF(C31>E31,1," ") | H31: =IF(C31="","",+IF(C31=E31,1," ")) | I31: =IF(C31<E31,1," ") | J31: 2 | K31: ='Grupp C'!L8 -> Marocko | L31: ='Grupp C'!M8 -> 0 | M31: ='Grupp C'!N8 -> 0 | N31: ='Grupp C'!O8 -> 0 | O31: ='Grupp C'!P8 -> 0 | P31: ='Grupp C'!Q8 -> 0 | Q31: ='Grupp C'!R8 -> 0 | R31: ='Grupp C'!S8 -> 0 | S31: ='Grupp C'!T8 -> 0 | W31: =IF(AC31="","",AY31) | X31: =IF(AC31="","",BF31) | Y31: =IF(AK31=0,"",BG31) | AB31: =B31 -> Haiti | AD31: ― | AF31: =F31 -> Skottland | AG31: =IF(AC31>AE31,1," ") | AH31: =IF(AC31="","",+IF(AC31=AE31,1," ")) | AI31: =IF(AC31<AE31,1," ") | AJ31: 2 | AW31: =IF(C31=AC31,1,0)+IF(AE31=E31,1,0) -> 2 | AX31: --> | AY31: =IF(AW31=2,2,0) -> 2 | AZ31: =AG31+G31 -> #VALUE! | BA31: =AH31+H31 -> #VALUE! | BB31: =AI31+I31 -> #VALUE! | BC31: --> | BD31: =COUNTIF(AZ31:BB31,2) -> 0 | BE31: --> | BF31: =IF(BD31=1,1,0) -> 0 | BG31: =IF(AK31=K31,2,0) -> 0 | BK31: Uruguay
A32: M15 | B32: =BP86 -> Brasilien | D32: ― | F32: =BP88 -> Haiti | G32: =IF(C32>E32,1," ") | H32: =IF(C32="","",+IF(C32=E32,1," ")) | I32: =IF(C32<E32,1," ") | J32: 3 | K32: ='Grupp C'!L9 -> Haiti | L32: ='Grupp C'!M9 -> 0 | M32: ='Grupp C'!N9 -> 0 | N32: ='Grupp C'!O9 -> 0 | O32: ='Grupp C'!P9 -> 0 | P32: ='Grupp C'!Q9 -> 0 | Q32: ='Grupp C'!R9 -> 0 | R32: ='Grupp C'!S9 -> 0 | S32: ='Grupp C'!T9 -> 0 | W32: =IF(AC32="","",AY32) | X32: =IF(AC32="","",BF32) | Y32: =IF(AK32=0,"",BG32) | AB32: =B32 -> Brasilien | AD32: ― | AF32: =F32 -> Haiti | AG32: =IF(AC32>AE32,1," ") | AH32: =IF(AC32="","",+IF(AC32=AE32,1," ")) | AI32: =IF(AC32<AE32,1," ") | AJ32: 3 | AW32: =IF(C32=AC32,1,0)+IF(AE32=E32,1,0) -> 2 | AX32: --> | AY32: =IF(AW32=2,2,0) -> 2 | AZ32: =AG32+G32 -> #VALUE! | BA32: =AH32+H32 -> #VALUE! | BB32: =AI32+I32 -> #VALUE! | BC32: --> | BD32: =COUNTIF(AZ32:BB32,2) -> 0 | BE32: --> | BF32: =IF(BD32=1,1,0) -> 0 | BG32: =IF(AK32=K32,2,0) -> 0 | BK32: USA
A33: M16 | B33: =BP87 -> Marocko | D33: ― | F33: =BP89 -> Skottland | G33: =IF(C33>E33,1," ") | H33: =IF(C33="","",+IF(C33=E33,1," ")) | I33: =IF(C33<E33,1," ") | J33: 4 | K33: ='Grupp C'!L10 -> Skottland | L33: ='Grupp C'!M10 -> 0 | M33: ='Grupp C'!N10 -> 0 | N33: ='Grupp C'!O10 -> 0 | O33: ='Grupp C'!P10 -> 0 | P33: ='Grupp C'!Q10 -> 0 | Q33: ='Grupp C'!R10 -> 0 | R33: ='Grupp C'!S10 -> 0 | S33: ='Grupp C'!T10 -> 0 | W33: =IF(AC33="","",AY33) | X33: =IF(AC33="","",BF33) | Y33: =IF(AK33=0,"",BG33) | AB33: =B33 -> Marocko | AD33: ― | AF33: =F33 -> Skottland | AG33: =IF(AC33>AE33,1," ") | AH33: =IF(AC33="","",+IF(AC33=AE33,1," ")) | AI33: =IF(AC33<AE33,1," ") | AJ33: 4 | AW33: =IF(C33=AC33,1,0)+IF(AE33=E33,1,0) -> 2 | AX33: --> | AY33: =IF(AW33=2,2,0) -> 2 | AZ33: =AG33+G33 -> #VALUE! | BA33: =AH33+H33 -> #VALUE! | BB33: =AI33+I33 -> #VALUE! | BC33: --> | BD33: =COUNTIF(AZ33:BB33,2) -> 0 | BE33: --> | BF33: =IF(BD33=1,1,0) -> 0 | BG33: =IF(AK33=K33,2,0) -> 0 | BK33: Wales
A34: M17 | B34: =BP86 -> Brasilien | D34: ― | F34: =BP89 -> Skottland | G34: =IF(C34>E34,1," ") | H34: =IF(C34="","",+IF(C34=E34,1," ")) | I34: =IF(C34<E34,1," ") | W34: =IF(AC34="","",AY34) | X34: =IF(AC34="","",BF34) | AB34: =B34 -> Brasilien | AD34: ― | AF34: =F34 -> Skottland | AG34: =IF(AC34>AE34,1," ") | AH34: =IF(AC34="","",+IF(AC34=AE34,1," ")) | AI34: =IF(AC34<AE34,1," ") | AW34: =IF(C34=AC34,1,0)+IF(AE34=E34,1,0) -> 2 | AX34: --> | AY34: =IF(AW34=2,2,0) -> 2 | AZ34: =AG34+G34 -> #VALUE! | BA34: =AH34+H34 -> #VALUE! | BB34: =AI34+I34 -> #VALUE! | BC34: --> | BD34: =COUNTIF(AZ34:BB34,2) -> 0 | BE34: --> | BF34: =IF(BD34=1,1,0) -> 0 | BK34: Mål
A35: M18 | B35: =BP87 -> Marocko | D35: ― | F35: =BP88 -> Haiti | G35: =IF(C35>E35,1," ") | H35: =IF(C35="","",+IF(C35=E35,1," ")) | I35: =IF(C35<E35,1," ") | W35: =IF(AC35="","",AY35) | X35: =IF(AC35="","",BF35) | AB35: =B35 -> Marocko | AD35: ― | AF35: =F35 -> Haiti | AG35: =IF(AC35>AE35,1," ") | AH35: =IF(AC35="","",+IF(AC35=AE35,1," ")) | AI35: =IF(AC35<AE35,1," ") | AW35: =IF(C35=AC35,1,0)+IF(AE35=E35,1,0) -> 2 | AX35: --> | AY35: =IF(AW35=2,2,0) -> 2 | AZ35: =AG35+G35 -> #VALUE! | BA35: =AH35+H35 -> #VALUE! | BB35: =AI35+I35 -> #VALUE! | BC35: --> | BD35: =COUNTIF(AZ35:BB35,2) -> 0 | BE35: --> | BF35: =IF(BD35=1,1,0) -> 0 | BK35: 0
W36: =SUM(W30:Y35) -> 0 | X36: av | Y36: Max 26 | BK36: 1
B37: Grupp D | G37: 1 | H37: X | I37: 2 | K37: Grupp D | L37: S | M37: V | N37: O | O37: F | P37: GM | Q37: IM | R37: M+/- | S37: Poäng | AB37: Grupp D | AG37: 1 | AH37: X | AI37: 2 | AK37: Grupp D | BK37: 2
A38: M19 | B38: =BP91 -> USA | D38: ― | F38: =BP92 -> Paraguay | G38: =IF(C38>E38,1," ") | H38: =IF(C38="","",+IF(C38=E38,1," ")) | I38: =IF(C38<E38,1," ") | J38: 1 | K38: ='Grupp D'!L7 -> USA | L38: ='Grupp D'!M7 -> 0 | M38: ='Grupp D'!N7 -> 0 | N38: ='Grupp D'!O7 -> 0 | O38: ='Grupp D'!P7 -> 0 | P38: ='Grupp D'!Q7 -> 0 | Q38: ='Grupp D'!R7 -> 0 | R38: ='Grupp D'!S7 -> 0 | S38: ='Grupp D'!T7 -> 0 | W38: =IF(AC38="","",AY38) | X38: =IF(AC38="","",BF38) | Y38: =IF(AK38=0,"",BG38) | AB38: =B38 -> USA | AD38: ― | AF38: =F38 -> Paraguay | AG38: =IF(AC38>AE38,1," ") | AH38: =IF(AC38="","",+IF(AC38=AE38,1," ")) | AI38: =IF(AC38<AE38,1," ") | AJ38: 1 | AW38: =IF(C38=AC38,1,0)+IF(AE38=E38,1,0) -> 2 | AX38: --> | AY38: =IF(AW38=2,2,0) -> 2 | AZ38: =AG38+G38 -> #VALUE! | BA38: =AH38+H38 -> #VALUE! | BB38: =AI38+I38 -> #VALUE! | BC38: --> | BD38: =COUNTIF(AZ38:BB38,2) -> 0 | BE38: --> | BF38: =IF(BD38=1,1,0) -> 0 | BG38: =IF(AK38=K38,2,0) -> 0 | BK38: 3
A39: M20 | B39: =BP93 -> Australien | D39: ― | F39: =BP94 -> Turkiet | G39: =IF(C39>E39,1," ") | H39: =IF(C39="","",+IF(C39=E39,1," ")) | I39: =IF(C39<E39,1," ") | J39: 2 | K39: ='Grupp D'!L8 -> Paraguay | L39: ='Grupp D'!M8 -> 0 | M39: ='Grupp D'!N8 -> 0 | N39: ='Grupp D'!O8 -> 0 | O39: ='Grupp D'!P8 -> 0 | P39: ='Grupp D'!Q8 -> 0 | Q39: ='Grupp D'!R8 -> 0 | R39: ='Grupp D'!S8 -> 0 | S39: ='Grupp D'!T8 -> 0 | W39: =IF(AC39="","",AY39) | X39: =IF(AC39="","",BF39) | Y39: =IF(AK39=0,"",BG39) | AB39: =B39 -> Australien | AD39: ― | AF39: =F39 -> Turkiet | AG39: =IF(AC39>AE39,1," ") | AH39: =IF(AC39="","",+IF(AC39=AE39,1," ")) | AI39: =IF(AC39<AE39,1," ") | AJ39: 2 | AW39: =IF(C39=AC39,1,0)+IF(AE39=E39,1,0) -> 2 | AX39: --> | AY39: =IF(AW39=2,2,0) -> 2 | AZ39: =AG39+G39 -> #VALUE! | BA39: =AH39+H39 -> #VALUE! | BB39: =AI39+I39 -> #VALUE! | BC39: --> | BD39: =COUNTIF(AZ39:BB39,2) -> 0 | BE39: --> | BF39: =IF(BD39=1,1,0) -> 0 | BG39: =IF(AK39=K39,2,0) -> 0 | BK39: 4
A40: M21 | B40: =BP91 -> USA | D40: ― | F40: =BP93 -> Australien | G40: =IF(C40>E40,1," ") | H40: =IF(C40="","",+IF(C40=E40,1," ")) | I40: =IF(C40<E40,1," ") | J40: 3 | K40: ='Grupp D'!L9 -> Australien | L40: ='Grupp D'!M9 -> 0 | M40: ='Grupp D'!N9 -> 0 | N40: ='Grupp D'!O9 -> 0 | O40: ='Grupp D'!P9 -> 0 | P40: ='Grupp D'!Q9 -> 0 | Q40: ='Grupp D'!R9 -> 0 | R40: ='Grupp D'!S9 -> 0 | S40: ='Grupp D'!T9 -> 0 | W40: =IF(AC40="","",AY40) | X40: =IF(AC40="","",BF40) | Y40: =IF(AK40=0,"",BG40) | AB40: =B40 -> USA | AD40: ― | AF40: =F40 -> Australien | AG40: =IF(AC40>AE40,1," ") | AH40: =IF(AC40="","",+IF(AC40=AE40,1," ")) | AI40: =IF(AC40<AE40,1," ") | AJ40: 3 | AW40: =IF(C40=AC40,1,0)+IF(AE40=E40,1,0) -> 2 | AX40: --> | AY40: =IF(AW40=2,2,0) -> 2 | AZ40: =AG40+G40 -> #VALUE! | BA40: =AH40+H40 -> #VALUE! | BB40: =AI40+I40 -> #VALUE! | BC40: --> | BD40: =COUNTIF(AZ40:BB40,2) -> 0 | BE40: --> | BF40: =IF(BD40=1,1,0) -> 0 | BG40: =IF(AK40=K40,2,0) -> 0 | BK40: 5
...

Sheet 8 bästa grupp 3or
B2: 8 bästa grupp 3or
B4: Lag | G4: Poäng
AG5: Grupp A
K6: Nn | L6: Teams | M6: P | N6: W | O6: D | P6: L | Q6: Ga | R6: Gf | S6: G+/- | T6: Points | U6: rank | V6: Teams | W6: P | X6: W | Y6: D | Z6: L | AA6: Ga | AB6: Gf | AC6: G+/- | AD6: Points | AE6: Criteria for rank | AF6: Grupp | AG6: ='VM-tipset 2026 mall'!BP76 -> Mexiko
K7: 1 | L7: =VLOOKUP($K7,$U$6:$AD$18,COLUMNS($L$7:L7)+1,FALSE) -> Sydkorea | M7: =VLOOKUP($K7,$U$6:$AD$18,COLUMNS($L$7:M7)+1,FALSE) -> 0 | N7: =VLOOKUP($K7,$U$6:$AD$18,COLUMNS($L$7:N7)+1,FALSE) -> 0 | O7: =VLOOKUP($K7,$U$6:$AD$18,COLUMNS($L$7:O7)+1,FALSE) -> 0 | P7: =VLOOKUP($K7,$U$6:$AD$18,COLUMNS($L$7:P7)+1,FALSE) -> 0 | Q7: =VLOOKUP($K7,$U$6:$AD$18,COLUMNS($L$7:Q7)+1,FALSE) -> 0 | R7: =VLOOKUP($K7,$U$6:$AD$18,COLUMNS($L$7:R7)+1,FALSE) -> 0 | S7: =VLOOKUP($K7,$U$6:$AD$18,COLUMNS($L$7:S7)+1,FALSE) -> 0 | T7: =VLOOKUP($K7,$U$6:$AD$18,COLUMNS($L$7:T7)+1,FALSE) -> 0 | U7: =RANK(AE7,$AE$7:$AE$18,0)+COUNTIF($AE$6:AE6,AE7) -> 1 | V7: ='VM-tipset 2026 mall'!K16 -> Sydkorea | W7: ='VM-tipset 2026 mall'!L16 -> 0 | X7: ='VM-tipset 2026 mall'!M16 -> 0 | Y7: ='VM-tipset 2026 mall'!N16 -> 0 | Z7: ='VM-tipset 2026 mall'!O16 -> 0 | AA7: ='VM-tipset 2026 mall'!P16 -> 0 | AB7: ='VM-tipset 2026 mall'!Q16 -> 0 | AC7: ='VM-tipset 2026 mall'!R16 -> 0 | AD7: ='VM-tipset 2026 mall'!S16 -> 0 | AE7: =SUM(AD7*1000000+AC7*10000+AA7*100+X7*10) -> 0 | AF7: A | AG7: ='VM-tipset 2026 mall'!BP77 -> Sydafrika
K8: 2 | L8: =VLOOKUP($K8,$U$6:$AD$18,COLUMNS($L$7:L8)+1,FALSE) -> Qatar | M8: =VLOOKUP($K8,$U$6:$AD$18,COLUMNS($L$7:M8)+1,FALSE) -> 0 | N8: =VLOOKUP($K8,$U$6:$AD$18,COLUMNS($L$7:N8)+1,FALSE) -> 0 | O8: =VLOOKUP($K8,$U$6:$AD$18,COLUMNS($L$7:O8)+1,FALSE) -> 0 | P8: =VLOOKUP($K8,$U$6:$AD$18,COLUMNS($L$7:P8)+1,FALSE) -> 0 | Q8: =VLOOKUP($K8,$U$6:$AD$18,COLUMNS($L$7:Q8)+1,FALSE) -> 0 | R8: =VLOOKUP($K8,$U$6:$AD$18,COLUMNS($L$7:R8)+1,FALSE) -> 0 | S8: =VLOOKUP($K8,$U$6:$AD$18,COLUMNS($L$7:S8)+1,FALSE) -> 0 | T8: =VLOOKUP($K8,$U$6:$AD$18,COLUMNS($L$7:T8)+1,FALSE) -> 0 | U8: =RANK(AE8,$AE$7:$AE$18,0)+COUNTIF($AE$6:AE7,AE8) -> 2 | V8: ='VM-tipset 2026 mall'!K24 -> Qatar | W8: ='VM-tipset 2026 mall'!L24 -> 0 | X8: ='VM-tipset 2026 mall'!M24 -> 0 | Y8: ='VM-tipset 2026 mall'!N24 -> 0 | Z8: ='VM-tipset 2026 mall'!O24 -> 0 | AA8: ='VM-tipset 2026 mall'!P24 -> 0 | AB8: ='VM-tipset 2026 mall'!Q24 -> 0 | AC8: ='VM-tipset 2026 mall'!R24 -> 0 | AD8: ='VM-tipset 2026 mall'!S24 -> 0 | AE8: =SUM(AD8*1000000+AC8*10000+AA8*100+X8*10) -> 0 | AF8: B | AG8: ='VM-tipset 2026 mall'!BP78 -> Sydkorea
K9: 3 | L9: =VLOOKUP($K9,$U$6:$AD$18,COLUMNS($L$7:L9)+1,FALSE) -> Haiti | M9: =VLOOKUP($K9,$U$6:$AD$18,COLUMNS($L$7:M9)+1,FALSE) -> 0 | N9: =VLOOKUP($K9,$U$6:$AD$18,COLUMNS($L$7:N9)+1,FALSE) -> 0 | O9: =VLOOKUP($K9,$U$6:$AD$18,COLUMNS($L$7:O9)+1,FALSE) -> 0 | P9: =VLOOKUP($K9,$U$6:$AD$18,COLUMNS($L$7:P9)+1,FALSE) -> 0 | Q9: =VLOOKUP($K9,$U$6:$AD$18,COLUMNS($L$7:Q9)+1,FALSE) -> 0 | R9: =VLOOKUP($K9,$U$6:$AD$18,COLUMNS($L$7:R9)+1,FALSE) -> 0 | S9: =VLOOKUP($K9,$U$6:$AD$18,COLUMNS($L$7:S9)+1,FALSE) -> 0 | T9: =VLOOKUP($K9,$U$6:$AD$18,COLUMNS($L$7:T9)+1,FALSE) -> 0 | U9: =RANK(AE9,$AE$7:$AE$18,0)+COUNTIF($AE$6:AE8,AE9) -> 3 | V9: ='VM-tipset 2026 mall'!K32 -> Haiti | W9: ='VM-tipset 2026 mall'!L32 -> 0 | X9: ='VM-tipset 2026 mall'!M32 -> 0 | Y9: ='VM-tipset 2026 mall'!N32 -> 0 | Z9: ='VM-tipset 2026 mall'!O32 -> 0 | AA9: ='VM-tipset 2026 mall'!P32 -> 0 | AB9: ='VM-tipset 2026 mall'!Q32 -> 0 | AC9: ='VM-tipset 2026 mall'!R32 -> 0 | AD9: ='VM-tipset 2026 mall'!S32 -> 0 | AE9: =SUM(AD9*1000000+AC9*10000+AA9*100+X9*10) -> 0 | AF9: C | AG9: ='VM-tipset 2026 mall'!BP79 -> Tjeckien
K10: 4 | L10: =VLOOKUP($K10,$U$6:$AD$18,COLUMNS($L$7:L10)+1,FALSE) -> Australien | M10: =VLOOKUP($K10,$U$6:$AD$18,COLUMNS($L$7:M10)+1,FALSE) -> 0 | N10: =VLOOKUP($K10,$U$6:$AD$18,COLUMNS($L$7:N10)+1,FALSE) -> 0 | O10: =VLOOKUP($K10,$U$6:$AD$18,COLUMNS($L$7:O10)+1,FALSE) -> 0 | P10: =VLOOKUP($K10,$U$6:$AD$18,COLUMNS($L$7:P10)+1,FALSE) -> 0 | Q10: =VLOOKUP($K10,$U$6:$AD$18,COLUMNS($L$7:Q10)+1,FALSE) -> 0 | R10: =VLOOKUP($K10,$U$6:$AD$18,COLUMNS($L$7:R10)+1,FALSE) -> 0 | S10: =VLOOKUP($K10,$U$6:$AD$18,COLUMNS($L$7:S10)+1,FALSE) -> 0 | T10: =VLOOKUP($K10,$U$6:$AD$18,COLUMNS($L$7:T10)+1,FALSE) -> 0 | U10: =RANK(AE10,$AE$7:$AE$18,0)+COUNTIF($AE$6:AE9,AE10) -> 4 | V10: ='VM-tipset 2026 mall'!K40 -> Australien | W10: ='VM-tipset 2026 mall'!L40 -> 0 | X10: ='VM-tipset 2026 mall'!M40 -> 0 | Y10: ='VM-tipset 2026 mall'!N40 -> 0 | Z10: ='VM-tipset 2026 mall'!O40 -> 0 | AA10: ='VM-tipset 2026 mall'!P40 -> 0 | AB10: ='VM-tipset 2026 mall'!Q40 -> 0 | AC10: ='VM-tipset 2026 mall'!R40 -> 0 | AD10: ='VM-tipset 2026 mall'!S40 -> 0 | AE10: =SUM(AD10*1000000+AC10*10000+AA10*100+X10*10) -> 0 | AF10: D
K11: 5 | L11: =VLOOKUP($K11,$U$6:$AD$18,COLUMNS($L$7:L11)+1,FALSE) -> Elfenbenskusten | M11: =VLOOKUP($K11,$U$6:$AD$18,COLUMNS($L$7:M11)+1,FALSE) -> 0 | N11: =VLOOKUP($K11,$U$6:$AD$18,COLUMNS($L$7:N11)+1,FALSE) -> 0 | O11: =VLOOKUP($K11,$U$6:$AD$18,COLUMNS($L$7:O11)+1,FALSE) -> 0 | P11: =VLOOKUP($K11,$U$6:$AD$18,COLUMNS($L$7:P11)+1,FALSE) -> 0 | Q11: =VLOOKUP($K11,$U$6:$AD$18,COLUMNS($L$7:Q11)+1,FALSE) -> 0 | R11: =VLOOKUP($K11,$U$6:$AD$18,COLUMNS($L$7:R11)+1,FALSE) -> 0 | S11: =VLOOKUP($K11,$U$6:$AD$18,COLUMNS($L$7:S11)+1,FALSE) -> 0 | T11: =VLOOKUP($K11,$U$6:$AD$18,COLUMNS($L$7:T11)+1,FALSE) -> 0 | U11: =RANK(AE11,$AE$7:$AE$18,0)+COUNTIF($AE$6:AE10,AE11) -> 5 | V11: ='VM-tipset 2026 mall'!K48 -> Elfenbenskusten | W11: ='VM-tipset 2026 mall'!L48 -> 0 | X11: ='VM-tipset 2026 mall'!M48 -> 0 | Y11: ='VM-tipset 2026 mall'!N48 -> 0 | Z11: ='VM-tipset 2026 mall'!O48 -> 0 | AA11: ='VM-tipset 2026 mall'!P48 -> 0 | AB11: ='VM-tipset 2026 mall'!Q48 -> 0 | AC11: ='VM-tipset 2026 mall'!R48 -> 0 | AD11: ='VM-tipset 2026 mall'!S48 -> 0 | AE11: =SUM(AD11*1000000+AC11*10000+AA11*100+X11*10) -> 0 | AF11: E
K12: 6 | L12: =VLOOKUP($K12,$U$6:$AD$18,COLUMNS($L$7:L12)+1,FALSE) -> Sverige | M12: =VLOOKUP($K12,$U$6:$AD$18,COLUMNS($L$7:M12)+1,FALSE) -> 0 | N12: =VLOOKUP($K12,$U$6:$AD$18,COLUMNS($L$7:N12)+1,FALSE) -> 0 | O12: =VLOOKUP($K12,$U$6:$AD$18,COLUMNS($L$7:O12)+1,FALSE) -> 0 | P12: =VLOOKUP($K12,$U$6:$AD$18,COLUMNS($L$7:P12)+1,FALSE) -> 0 | Q12: =VLOOKUP($K12,$U$6:$AD$18,COLUMNS($L$7:Q12)+1,FALSE) -> 0 | R12: =VLOOKUP($K12,$U$6:$AD$18,COLUMNS($L$7:R12)+1,FALSE) -> 0 | S12: =VLOOKUP($K12,$U$6:$AD$18,COLUMNS($L$7:S12)+1,FALSE) -> 0 | T12: =VLOOKUP($K12,$U$6:$AD$18,COLUMNS($L$7:T12)+1,FALSE) -> 0 | U12: =RANK(AE12,$AE$7:$AE$18,0)+COUNTIF($AE$6:AE11,AE12) -> 6 | V12: ='VM-tipset 2026 mall'!K56 -> Sverige | W12: ='VM-tipset 2026 mall'!L56 -> 0 | X12: ='VM-tipset 2026 mall'!M56 -> 0 | Y12: ='VM-tipset 2026 mall'!N56 -> 0 | Z12: ='VM-tipset 2026 mall'!O56 -> 0 | AA12: ='VM-tipset 2026 mall'!P56 -> 0 | AB12: ='VM-tipset 2026 mall'!Q56 -> 0 | AC12: ='VM-tipset 2026 mall'!R56 -> 0 | AD12: ='VM-tipset 2026 mall'!S56 -> 0 | AE12: =SUM(AD12*1000000+AC12*10000+AA12*100+X12*10) -> 0 | AF12: F
K13: 7 | L13: =VLOOKUP($K13,$U$6:$AD$18,COLUMNS($L$7:L13)+1,FALSE) -> Iran | M13: =VLOOKUP($K13,$U$6:$AD$18,COLUMNS($L$7:M13)+1,FALSE) -> 0 | N13: =VLOOKUP($K13,$U$6:$AD$18,COLUMNS($L$7:N13)+1,FALSE) -> 0 | O13: =VLOOKUP($K13,$U$6:$AD$18,COLUMNS($L$7:O13)+1,FALSE) -> 0 | P13: =VLOOKUP($K13,$U$6:$AD$18,COLUMNS($L$7:P13)+1,FALSE) -> 0 | Q13: =VLOOKUP($K13,$U$6:$AD$18,COLUMNS($L$7:Q13)+1,FALSE) -> 0 | R13: =VLOOKUP($K13,$U$6:$AD$18,COLUMNS($L$7:R13)+1,FALSE) -> 0 | S13: =VLOOKUP($K13,$U$6:$AD$18,COLUMNS($L$7:S13)+1,FALSE) -> 0 | T13: =VLOOKUP($K13,$U$6:$AD$18,COLUMNS($L$7:T13)+1,FALSE) -> 0 | U13: =RANK(AE13,$AE$7:$AE$18,0)+COUNTIF($AE$6:AE12,AE13) -> 7 | V13: ='VM-tipset 2026 mall'!K64 -> Iran | W13: ='VM-tipset 2026 mall'!L64 -> 0 | X13: ='VM-tipset 2026 mall'!M64 -> 0 | Y13: ='VM-tipset 2026 mall'!N64 -> 0 | Z13: ='VM-tipset 2026 mall'!O64 -> 0 | AA13: ='VM-tipset 2026 mall'!P64 -> 0 | AB13: ='VM-tipset 2026 mall'!Q64 -> 0 | AC13: ='VM-tipset 2026 mall'!R64 -> 0 | AD13: ='VM-tipset 2026 mall'!S64 -> 0 | AE13: =SUM(AD13*1000000+AC13*10000+AA13*100+X13*10) -> 0 | AF13: G
K14: 8 | L14: =VLOOKUP($K14,$U$6:$AD$18,COLUMNS($L$7:L14)+1,FALSE) -> Saudiarabien | M14: =VLOOKUP($K14,$U$6:$AD$18,COLUMNS($L$7:M14)+1,FALSE) -> 0 | N14: =VLOOKUP($K14,$U$6:$AD$18,COLUMNS($L$7:N14)+1,FALSE) -> 0 | O14: =VLOOKUP($K14,$U$6:$AD$18,COLUMNS($L$7:O14)+1,FALSE) -> 0 | P14: =VLOOKUP($K14,$U$6:$AD$18,COLUMNS($L$7:P14)+1,FALSE) -> 0 | Q14: =VLOOKUP($K14,$U$6:$AD$18,COLUMNS($L$7:Q14)+1,FALSE) -> 0 | R14: =VLOOKUP($K14,$U$6:$AD$18,COLUMNS($L$7:R14)+1,FALSE) -> 0 | S14: =VLOOKUP($K14,$U$6:$AD$18,COLUMNS($L$7:S14)+1,FALSE) -> 0 | T14: =VLOOKUP($K14,$U$6:$AD$18,COLUMNS($L$7:T14)+1,FALSE) -> 0 | U14: =RANK(AE14,$AE$7:$AE$18,0)+COUNTIF($AE$6:AE13,AE14) -> 8 | V14: ='VM-tipset 2026 mall'!K72 -> Saudiarabien | W14: ='VM-tipset 2026 mall'!L72 -> 0 | X14: ='VM-tipset 2026 mall'!M72 -> 0 | Y14: ='VM-tipset 2026 mall'!N72 -> 0 | Z14: ='VM-tipset 2026 mall'!O72 -> 0 | AA14: ='VM-tipset 2026 mall'!P72 -> 0 | AB14: ='VM-tipset 2026 mall'!Q72 -> 0 | AC14: ='VM-tipset 2026 mall'!R72 -> 0 | AD14: ='VM-tipset 2026 mall'!S72 -> 0 | AE14: =SUM(AD14*1000000+AC14*10000+AA14*100+X14*10) -> 0 | AF14: H
K15: 9 | L15: =VLOOKUP($K15,$U$6:$AD$18,COLUMNS($L$7:L15)+1,FALSE) -> Irak | M15: =VLOOKUP($K15,$U$6:$AD$18,COLUMNS($L$7:M15)+1,FALSE) -> 0 | N15: =VLOOKUP($K15,$U$6:$AD$18,COLUMNS($L$7:N15)+1,FALSE) -> 0 | O15: =VLOOKUP($K15,$U$6:$AD$18,COLUMNS($L$7:O15)+1,FALSE) -> 0 | P15: =VLOOKUP($K15,$U$6:$AD$18,COLUMNS($L$7:P15)+1,FALSE) -> 0 | Q15: =VLOOKUP($K15,$U$6:$AD$18,COLUMNS($L$7:Q15)+1,FALSE) -> 0 | R15: =VLOOKUP($K15,$U$6:$AD$18,COLUMNS($L$7:R15)+1,FALSE) -> 0 | S15: =VLOOKUP($K15,$U$6:$AD$18,COLUMNS($L$7:S15)+1,FALSE) -> 0 | T15: =VLOOKUP($K15,$U$6:$AD$18,COLUMNS($L$7:T15)+1,FALSE) -> 0 | U15: =RANK(AE15,$AE$7:$AE$18,0)+COUNTIF($AE$6:AE14,AE15) -> 9 | V15: ='VM-tipset 2026 mall'!K80 -> Irak | W15: ='VM-tipset 2026 mall'!L80 -> 0 | X15: ='VM-tipset 2026 mall'!M80 -> 0 | Y15: ='VM-tipset 2026 mall'!N80 -> 0 | Z15: ='VM-tipset 2026 mall'!O80 -> 0 | AA15: ='VM-tipset 2026 mall'!P80 -> 0 | AB15: ='VM-tipset 2026 mall'!Q80 -> 0 | AC15: ='VM-tipset 2026 mall'!R80 -> 0 | AD15: ='VM-tipset 2026 mall'!S80 -> 0 | AE15: =SUM(AD15*1000000+AC15*10000+AA15*100+X15*10) -> 0 | AF15: I
K16: 10 | L16: =VLOOKUP($K16,$U$6:$AD$18,COLUMNS($L$7:L16)+1,FALSE) -> Österrike | M16: =VLOOKUP($K16,$U$6:$AD$18,COLUMNS($L$7:M16)+1,FALSE) -> 0 | N16: =VLOOKUP($K16,$U$6:$AD$18,COLUMNS($L$7:N16)+1,FALSE) -> 0 | O16: =VLOOKUP($K16,$U$6:$AD$18,COLUMNS($L$7:O16)+1,FALSE) -> 0 | P16: =VLOOKUP($K16,$U$6:$AD$18,COLUMNS($L$7:P16)+1,FALSE) -> 0 | Q16: =VLOOKUP($K16,$U$6:$AD$18,COLUMNS($L$7:Q16)+1,FALSE) -> 0 | R16: =VLOOKUP($K16,$U$6:$AD$18,COLUMNS($L$7:R16)+1,FALSE) -> 0 | S16: =VLOOKUP($K16,$U$6:$AD$18,COLUMNS($L$7:S16)+1,FALSE) -> 0 | T16: =VLOOKUP($K16,$U$6:$AD$18,COLUMNS($L$7:T16)+1,FALSE) -> 0 | U16: =RANK(AE16,$AE$7:$AE$18,0)+COUNTIF($AE$6:AE15,AE16) -> 10 | V16: ='VM-tipset 2026 mall'!K88 -> Österrike | W16: ='VM-tipset 2026 mall'!L88 -> 0 | X16: ='VM-tipset 2026 mall'!M88 -> 0 | Y16: ='VM-tipset 2026 mall'!N88 -> 0 | Z16: ='VM-tipset 2026 mall'!O88 -> 0 | AA16: ='VM-tipset 2026 mall'!P88 -> 0 | AB16: ='VM-tipset 2026 mall'!Q88 -> 0 | AC16: ='VM-tipset 2026 mall'!R88 -> 0 | AD16: ='VM-tipset 2026 mall'!S88 -> 0 | AE16: =SUM(AD16*1000000+AC16*10000+AA16*100+X16*10) -> 0 | AF16: J
K17: 11 | L17: =VLOOKUP($K17,$U$6:$AD$18,COLUMNS($L$7:L17)+1,FALSE) -> Uzbekistan | M17: =VLOOKUP($K17,$U$6:$AD$18,COLUMNS($L$7:M17)+1,FALSE) -> 0 | N17: =VLOOKUP($K17,$U$6:$AD$18,COLUMNS($L$7:N17)+1,FALSE) -> 0 | O17: =VLOOKUP($K17,$U$6:$AD$18,COLUMNS($L$7:O17)+1,FALSE) -> 0 | P17: =VLOOKUP($K17,$U$6:$AD$18,COLUMNS($L$7:P17)+1,FALSE) -> 0 | Q17: =VLOOKUP($K17,$U$6:$AD$18,COLUMNS($L$7:Q17)+1,FALSE) -> 0 | R17: =VLOOKUP($K17,$U$6:$AD$18,COLUMNS($L$7:R17)+1,FALSE) -> 0 | S17: =VLOOKUP($K17,$U$6:$AD$18,COLUMNS($L$7:S17)+1,FALSE) -> 0 | T17: =VLOOKUP($K17,$U$6:$AD$18,COLUMNS($L$7:T17)+1,FALSE) -> 0 | U17: =RANK(AE17,$AE$7:$AE$18,0)+COUNTIF($AE$6:AE16,AE17) -> 11 | V17: ='VM-tipset 2026 mall'!K96 -> Uzbekistan | W17: ='VM-tipset 2026 mall'!L96 -> 0 | X17: ='VM-tipset 2026 mall'!M96 -> 0 | Y17: ='VM-tipset 2026 mall'!N96 -> 0 | Z17: ='VM-tipset 2026 mall'!O96 -> 0 | AA17: ='VM-tipset 2026 mall'!P96 -> 0 | AB17: ='VM-tipset 2026 mall'!Q96 -> 0 | AC17: ='VM-tipset 2026 mall'!R96 -> 0 | AD17: ='VM-tipset 2026 mall'!S96 -> 0 | AE17: =SUM(AD17*1000000+AC17*10000+AA17*100+X17*10) -> 0 | AF17: K
K18: 12 | L18: =VLOOKUP($K18,$U$6:$AD$18,COLUMNS($L$7:L18)+1,FALSE) -> Ghana | M18: =VLOOKUP($K18,$U$6:$AD$18,COLUMNS($L$7:M18)+1,FALSE) -> 0 | N18: =VLOOKUP($K18,$U$6:$AD$18,COLUMNS($L$7:N18)+1,FALSE) -> 0 | O18: =VLOOKUP($K18,$U$6:$AD$18,COLUMNS($L$7:O18)+1,FALSE) -> 0 | P18: =VLOOKUP($K18,$U$6:$AD$18,COLUMNS($L$7:P18)+1,FALSE) -> 0 | Q18: =VLOOKUP($K18,$U$6:$AD$18,COLUMNS($L$7:Q18)+1,FALSE) -> 0 | R18: =VLOOKUP($K18,$U$6:$AD$18,COLUMNS($L$7:R18)+1,FALSE) -> 0 | S18: =VLOOKUP($K18,$U$6:$AD$18,COLUMNS($L$7:S18)+1,FALSE) -> 0 | T18: =VLOOKUP($K18,$U$6:$AD$18,COLUMNS($L$7:T18)+1,FALSE) -> 0 | U18: =RANK(AE18,$AE$7:$AE$18,0)+COUNTIF($AE$6:AE17,AE18) -> 12 | V18: ='VM-tipset 2026 mall'!K104 -> Ghana | W18: ='VM-tipset 2026 mall'!L104 -> 0 | X18: ='VM-tipset 2026 mall'!M104 -> 0 | Y18: ='VM-tipset 2026 mall'!N104 -> 0 | Z18: ='VM-tipset 2026 mall'!O104 -> 0 | AA18: ='VM-tipset 2026 mall'!P104 -> 0 | AB18: ='VM-tipset 2026 mall'!Q104 -> 0 | AC18: ='VM-tipset 2026 mall'!R104 -> 0 | AD18: ='VM-tipset 2026 mall'!S104 -> 0 | AE18: =SUM(AD18*1000000+AC18*10000+AA18*100+X18*10) -> 0 | AF18: L

Sheet Grupp A
B2: Grupp A
B4: Lag | G4: Poäng
B5: ='VM-tipset 2026 mall'!B14 -> Mexiko | C5: ='VM-tipset 2026 mall'!C14 | D5: ='VM-tipset 2026 mall'!E14 | E5: ='VM-tipset 2026 mall'!F14 -> Sydafrika | G5: =IF(C5="","",IF(C5>D5,3,IF(C5=D5,1,0))) | H5: =IF(D5="","",IF(D5>C5,3,IF(D5=C5,1,0))) | AG5: Grupp A
B6: ='VM-tipset 2026 mall'!B15 -> Sydkorea | C6: ='VM-tipset 2026 mall'!C15 | D6: ='VM-tipset 2026 mall'!E15 | E6: ='VM-tipset 2026 mall'!F15 -> Tjeckien | G6: =IF(C6="","",IF(C6>D6,3,IF(C6=D6,1,0))) | H6: =IF(D6="","",IF(D6>C6,3,IF(D6=C6,1,0))) | K6: Nn | L6: Teams | M6: P | N6: W | O6: D | P6: L | Q6: Ga | R6: Gf | S6: G+/- | T6: Points | U6: rank | V6: Teams | W6: P | X6: W | Y6: D | Z6: L | AA6: Ga | AB6: Gf | AC6: G+/- | AD6: Points | AE6: Criteria for rank | AG6: ='VM-tipset 2026 mall'!BP76 -> Mexiko
B7: ='VM-tipset 2026 mall'!B16 -> Mexiko | C7: ='VM-tipset 2026 mall'!C16 | D7: ='VM-tipset 2026 mall'!E16 | E7: ='VM-tipset 2026 mall'!F16 -> Sydkorea | G7: =IF(C7="","",IF(C7>D7,3,IF(C7=D7,1,0))) | H7: =IF(D7="","",IF(D7>C7,3,IF(D7=C7,1,0))) | K7: 1 | L7: =VLOOKUP($K7,$U$6:$AD$10,COLUMNS($L$7:L7)+1,FALSE) -> Mexiko | M7: =VLOOKUP($K7,$U$6:$AD$10,COLUMNS($L$7:M7)+1,FALSE) -> 0 | N7: =VLOOKUP($K7,$U$6:$AD$10,COLUMNS($L$7:N7)+1,FALSE) -> 0 | O7: =VLOOKUP($K7,$U$6:$AD$10,COLUMNS($L$7:O7)+1,FALSE) -> 0 | P7: =VLOOKUP($K7,$U$6:$AD$10,COLUMNS($L$7:P7)+1,FALSE) -> 0 | Q7: =VLOOKUP($K7,$U$6:$AD$10,COLUMNS($L$7:Q7)+1,FALSE) -> 0 | R7: =VLOOKUP($K7,$U$6:$AD$10,COLUMNS($L$7:R7)+1,FALSE) -> 0 | S7: =VLOOKUP($K7,$U$6:$AD$10,COLUMNS($L$7:S7)+1,FALSE) -> 0 | T7: =VLOOKUP($K7,$U$6:$AD$10,COLUMNS($L$7:T7)+1,FALSE) -> 0 | U7: =RANK(AE7,$AE$7:$AE$10,0)+COUNTIF($AE$6:AE6,AE7) -> 1 | V7: =+AG6 -> Mexiko | W7: =COUNTIFS($B$5:$B$10,V7,$C$5:$C$10,">=0")+COUNTIFS($E$5:$E$10,V7,$D$5:$D$10,">=0") -> 0 | X7: =COUNTIFS($B$5:$B$10,V7,$G$5:$G$10,3)+COUNTIFS($E$5:$E$10,V7,$H$5:$H$10,3) -> 0 | Y7: =COUNTIFS($B$5:$B$10,V7,$G$5:$G$10,1)+COUNTIFS($E$5:$E$10,V7,$H$5:$H$10,1) -> 0 | Z7: =COUNTIFS($B$5:$B$10,V7,$G$5:$G$10,0)+COUNTIFS($E$5:$E$10,V7,$H$5:$H$10,0) -> 0 | AA7: =SUMIF($B$5:$B$10,V7,$C$5:$C$10)+SUMIF($E$5:$E$10,V7,$D$5:$D$10) -> 0 | AB7: =SUMIF($B$5:$B$10,V7,$D$5:$D$10)+SUMIF($E$5:$E$10,V7,$C$5:$C$10) -> 0 | AC7: =+AA7-AB7 -> 0 | AD7: =SUMIF($B$5:$B$10,V7,$G$5:$G$10)+SUMIF($E$5:$E$10,V7,$H$5:$H$10) -> 0 | AE7: =SUM(AD7*1000000+AC7*10000+AA7*100+X7*10) -> 0 | AG7: ='VM-tipset 2026 mall'!BP77 -> Sydafrika
B8: ='VM-tipset 2026 mall'!B17 -> Sydafrika | C8: ='VM-tipset 2026 mall'!C17 | D8: ='VM-tipset 2026 mall'!E17 | E8: ='VM-tipset 2026 mall'!F17 -> Tjeckien | G8: =IF(C8="","",IF(C8>D8,3,IF(C8=D8,1,0))) | H8: =IF(D8="","",IF(D8>C8,3,IF(D8=C8,1,0))) | K8: 2 | L8: =VLOOKUP($K8,$U$6:$AD$10,COLUMNS($L$7:L8)+1,FALSE) -> Sydafrika | M8: =VLOOKUP($K8,$U$6:$AD$10,COLUMNS($L$7:M8)+1,FALSE) -> 0 | N8: =VLOOKUP($K8,$U$6:$AD$10,COLUMNS($L$7:N8)+1,FALSE) -> 0 | O8: =VLOOKUP($K8,$U$6:$AD$10,COLUMNS($L$7:O8)+1,FALSE) -> 0 | P8: =VLOOKUP($K8,$U$6:$AD$10,COLUMNS($L$7:P8)+1,FALSE) -> 0 | Q8: =VLOOKUP($K8,$U$6:$AD$10,COLUMNS($L$7:Q8)+1,FALSE) -> 0 | R8: =VLOOKUP($K8,$U$6:$AD$10,COLUMNS($L$7:R8)+1,FALSE) -> 0 | S8: =VLOOKUP($K8,$U$6:$AD$10,COLUMNS($L$7:S8)+1,FALSE) -> 0 | T8: =VLOOKUP($K8,$U$6:$AD$10,COLUMNS($L$7:T8)+1,FALSE) -> 0 | U8: =RANK(AE8,$AE$7:$AE$10,0)+COUNTIF($AE$6:AE7,AE8) -> 2 | V8: =+AG7 -> Sydafrika | W8: =COUNTIFS($B$5:$B$10,V8,$C$5:$C$10,">=0")+COUNTIFS($E$5:$E$10,V8,$D$5:$D$10,">=0") -> 0 | X8: =COUNTIFS($B$5:$B$10,V8,$G$5:$G$10,3)+COUNTIFS($E$5:$E$10,V8,$H$5:$H$10,3) -> 0 | Y8: =COUNTIFS($B$5:$B$10,V8,$G$5:$G$10,1)+COUNTIFS($E$5:$E$10,V8,$H$5:$H$10,1) -> 0 | Z8: =COUNTIFS($B$5:$B$10,V8,$G$5:$G$10,0)+COUNTIFS($E$5:$E$10,V8,$H$5:$H$10,0) -> 0 | AA8: =SUMIF($B$5:$B$10,V8,$C$5:$C$10)+SUMIF($E$5:$E$10,V8,$D$5:$D$10) -> 0 | AB8: =SUMIF($B$5:$B$10,V8,$D$5:$D$10)+SUMIF($E$5:$E$10,V8,$C$5:$C$10) -> 0 | AC8: =+AA8-AB8 -> 0 | AD8: =SUMIF($B$5:$B$10,V8,$G$5:$G$10)+SUMIF($E$5:$E$10,V8,$H$5:$H$10) -> 0 | AE8: =SUM(AD8*1000000+AC8*10000+AA8*100+X8*10) -> 0 | AG8: ='VM-tipset 2026 mall'!BP78 -> Sydkorea
B9: ='VM-tipset 2026 mall'!B18 -> Mexiko | C9: ='VM-tipset 2026 mall'!C18 | D9: ='VM-tipset 2026 mall'!E18 | E9: ='VM-tipset 2026 mall'!F18 -> Tjeckien | G9: =IF(C9="","",IF(C9>D9,3,IF(C9=D9,1,0))) | H9: =IF(D9="","",IF(D9>C9,3,IF(D9=C9,1,0))) | K9: 3 | L9: =VLOOKUP($K9,$U$6:$AD$10,COLUMNS($L$7:L9)+1,FALSE) -> Sydkorea | M9: =VLOOKUP($K9,$U$6:$AD$10,COLUMNS($L$7:M9)+1,FALSE) -> 0 | N9: =VLOOKUP($K9,$U$6:$AD$10,COLUMNS($L$7:N9)+1,FALSE) -> 0 | O9: =VLOOKUP($K9,$U$6:$AD$10,COLUMNS($L$7:O9)+1,FALSE) -> 0 | P9: =VLOOKUP($K9,$U$6:$AD$10,COLUMNS($L$7:P9)+1,FALSE) -> 0 | Q9: =VLOOKUP($K9,$U$6:$AD$10,COLUMNS($L$7:Q9)+1,FALSE) -> 0 | R9: =VLOOKUP($K9,$U$6:$AD$10,COLUMNS($L$7:R9)+1,FALSE) -> 0 | S9: =VLOOKUP($K9,$U$6:$AD$10,COLUMNS($L$7:S9)+1,FALSE) -> 0 | T9: =VLOOKUP($K9,$U$6:$AD$10,COLUMNS($L$7:T9)+1,FALSE) -> 0 | U9: =RANK(AE9,$AE$7:$AE$10,0)+COUNTIF($AE$6:AE8,AE9) -> 3 | V9: =+AG8 -> Sydkorea | W9: =COUNTIFS($B$5:$B$10,V9,$C$5:$C$10,">=0")+COUNTIFS($E$5:$E$10,V9,$D$5:$D$10,">=0") -> 0 | X9: =COUNTIFS($B$5:$B$10,V9,$G$5:$G$10,3)+COUNTIFS($E$5:$E$10,V9,$H$5:$H$10,3) -> 0 | Y9: =COUNTIFS($B$5:$B$10,V9,$G$5:$G$10,1)+COUNTIFS($E$5:$E$10,V9,$H$5:$H$10,1) -> 0 | Z9: =COUNTIFS($B$5:$B$10,V9,$G$5:$G$10,0)+COUNTIFS($E$5:$E$10,V9,$H$5:$H$10,0) -> 0 | AA9: =SUMIF($B$5:$B$10,V9,$C$5:$C$10)+SUMIF($E$5:$E$10,V9,$D$5:$D$10) -> 0 | AB9: =SUMIF($B$5:$B$10,V9,$D$5:$D$10)+SUMIF($E$5:$E$10,V9,$C$5:$C$10) -> 0 | AC9: =+AA9-AB9 -> 0 | AD9: =SUMIF($B$5:$B$10,V9,$G$5:$G$10)+SUMIF($E$5:$E$10,V9,$H$5:$H$10) -> 0 | AE9: =SUM(AD9*1000000+AC9*10000+AA9*100+X9*10) -> 0 | AG9: ='VM-tipset 2026 mall'!BP79 -> Tjeckien
B10: ='VM-tipset 2026 mall'!B19 -> Sydafrika | C10: ='VM-tipset 2026 mall'!C19 | D10: ='VM-tipset 2026 mall'!E19 | E10: ='VM-tipset 2026 mall'!F19 -> Sydkorea | G10: =IF(C10="","",IF(C10>D10,3,IF(C10=D10,1,0))) | H10: =IF(D10="","",IF(D10>C10,3,IF(D10=C10,1,0))) | K10: 4 | L10: =VLOOKUP($K10,$U$6:$AD$10,COLUMNS($L$7:L10)+1,FALSE) -> Tjeckien | M10: =VLOOKUP($K10,$U$6:$AD$10,COLUMNS($L$7:M10)+1,FALSE) -> 0 | N10: =VLOOKUP($K10,$U$6:$AD$10,COLUMNS($L$7:N10)+1,FALSE) -> 0 | O10: =VLOOKUP($K10,$U$6:$AD$10,COLUMNS($L$7:O10)+1,FALSE) -> 0 | P10: =VLOOKUP($K10,$U$6:$AD$10,COLUMNS($L$7:P10)+1,FALSE) -> 0 | Q10: =VLOOKUP($K10,$U$6:$AD$10,COLUMNS($L$7:Q10)+1,FALSE) -> 0 | R10: =VLOOKUP($K10,$U$6:$AD$10,COLUMNS($L$7:R10)+1,FALSE) -> 0 | S10: =VLOOKUP($K10,$U$6:$AD$10,COLUMNS($L$7:S10)+1,FALSE) -> 0 | T10: =VLOOKUP($K10,$U$6:$AD$10,COLUMNS($L$7:T10)+1,FALSE) -> 0 | U10: =RANK(AE10,$AE$7:$AE$10,0)+COUNTIF($AE$6:AE9,AE10) -> 4 | V10: =+AG9 -> Tjeckien | W10: =COUNTIFS($B$5:$B$10,V10,$C$5:$C$10,">=0")+COUNTIFS($E$5:$E$10,V10,$D$5:$D$10,">=0") -> 0 | X10: =COUNTIFS($B$5:$B$10,V10,$G$5:$G$10,3)+COUNTIFS($E$5:$E$10,V10,$H$5:$H$10,3) -> 0 | Y10: =COUNTIFS($B$5:$B$10,V10,$G$5:$G$10,1)+COUNTIFS($E$5:$E$10,V10,$H$5:$H$10,1) -> 0 | Z10: =COUNTIFS($B$5:$B$10,V10,$G$5:$G$10,0)+COUNTIFS($E$5:$E$10,V10,$H$5:$H$10,0) -> 0 | AA10: =SUMIF($B$5:$B$10,V10,$C$5:$C$10)+SUMIF($E$5:$E$10,V10,$D$5:$D$10) -> 0 | AB10: =SUMIF($B$5:$B$10,V10,$D$5:$D$10)+SUMIF($E$5:$E$10,V10,$C$5:$C$10) -> 0 | AC10: =+AA10-AB10 -> 0 | AD10: =SUMIF($B$5:$B$10,V10,$G$5:$G$10)+SUMIF($E$5:$E$10,V10,$H$5:$H$10) -> 0 | AE10: =SUM(AD10*1000000+AC10*10000+AA10*100+X10*10) -> 0

Sheet Grupp B
B2: Grupp B
B4: Lag | G4: Poäng
B5: ='VM-tipset 2026 mall'!B22 -> Kanada | C5: ='VM-tipset 2026 mall'!C22 | D5: ='VM-tipset 2026 mall'!E22 | E5: ='VM-tipset 2026 mall'!F22 -> Bosnien | G5: =IF(C5="","",IF(C5>D5,3,IF(C5=D5,1,0))) | H5: =IF(D5="","",IF(D5>C5,3,IF(D5=C5,1,0))) | AG5: Grupp B
B6: ='VM-tipset 2026 mall'!B23 -> Qatar | C6: ='VM-tipset 2026 mall'!C23 | D6: ='VM-tipset 2026 mall'!E23 | E6: ='VM-tipset 2026 mall'!F23 -> Schweiz | G6: =IF(C6="","",IF(C6>D6,3,IF(C6=D6,1,0))) | H6: =IF(D6="","",IF(D6>C6,3,IF(D6=C6,1,0))) | K6: Nn | L6: Teams | M6: P | N6: W | O6: D | P6: L | Q6: Ga | R6: Gf | S6: G+/- | T6: Points | U6: rank | V6: Teams | W6: P | X6: W | Y6: D | Z6: L | AA6: Ga | AB6: Gf | AC6: G+/- | AD6: Points | AE6: Criteria for rank | AG6: ='VM-tipset 2026 mall'!BP81 -> Kanada
B7: ='VM-tipset 2026 mall'!B24 -> Kanada | C7: ='VM-tipset 2026 mall'!C24 | D7: ='VM-tipset 2026 mall'!E24 | E7: ='VM-tipset 2026 mall'!F24 -> Qatar | G7: =IF(C7="","",IF(C7>D7,3,IF(C7=D7,1,0))) | H7: =IF(D7="","",IF(D7>C7,3,IF(D7=C7,1,0))) | K7: 1 | L7: =VLOOKUP($K7,$U$6:$AD$10,COLUMNS($L$7:L7)+1,FALSE) -> Kanada | M7: =VLOOKUP($K7,$U$6:$AD$10,COLUMNS($L$7:M7)+1,FALSE) -> 0 | N7: =VLOOKUP($K7,$U$6:$AD$10,COLUMNS($L$7:N7)+1,FALSE) -> 0 | O7: =VLOOKUP($K7,$U$6:$AD$10,COLUMNS($L$7:O7)+1,FALSE) -> 0 | P7: =VLOOKUP($K7,$U$6:$AD$10,COLUMNS($L$7:P7)+1,FALSE) -> 0 | Q7: =VLOOKUP($K7,$U$6:$AD$10,COLUMNS($L$7:Q7)+1,FALSE) -> 0 | R7: =VLOOKUP($K7,$U$6:$AD$10,COLUMNS($L$7:R7)+1,FALSE) -> 0 | S7: =VLOOKUP($K7,$U$6:$AD$10,COLUMNS($L$7:S7)+1,FALSE) -> 0 | T7: =VLOOKUP($K7,$U$6:$AD$10,COLUMNS($L$7:T7)+1,FALSE) -> 0 | U7: =RANK(AE7,$AE$7:$AE$10,0)+COUNTIF($AE$6:AE6,AE7) -> 1 | V7: =+AG6 -> Kanada | W7: =COUNTIFS($B$5:$B$10,V7,$C$5:$C$10,">=0")+COUNTIFS($E$5:$E$10,V7,$D$5:$D$10,">=0") -> 0 | X7: =COUNTIFS($B$5:$B$10,V7,$G$5:$G$10,3)+COUNTIFS($E$5:$E$10,V7,$H$5:$H$10,3) -> 0 | Y7: =COUNTIFS($B$5:$B$10,V7,$G$5:$G$10,1)+COUNTIFS($E$5:$E$10,V7,$H$5:$H$10,1) -> 0 | Z7: =COUNTIFS($B$5:$B$10,V7,$G$5:$G$10,0)+COUNTIFS($E$5:$E$10,V7,$H$5:$H$10,0) -> 0 | AA7: =SUMIF($B$5:$B$10,V7,$C$5:$C$10)+SUMIF($E$5:$E$10,V7,$D$5:$D$10) -> 0 | AB7: =SUMIF($B$5:$B$10,V7,$D$5:$D$10)+SUMIF($E$5:$E$10,V7,$C$5:$C$10) -> 0 | AC7: =+AA7-AB7 -> 0 | AD7: =SUMIF($B$5:$B$10,V7,$G$5:$G$10)+SUMIF($E$5:$E$10,V7,$H$5:$H$10) -> 0 | AE7: =SUM(AD7*1000000+AC7*10000+AA7*100+X7*10) -> 0 | AG7: ='VM-tipset 2026 mall'!BP82 -> Bosnien
B8: ='VM-tipset 2026 mall'!B25 -> Bosnien | C8: ='VM-tipset 2026 mall'!C25 | D8: ='VM-tipset 2026 mall'!E25 | E8: ='VM-tipset 2026 mall'!F25 -> Schweiz | G8: =IF(C8="","",IF(C8>D8,3,IF(C8=D8,1,0))) | H8: =IF(D8="","",IF(D8>C8,3,IF(D8=C8,1,0))) | K8: 2 | L8: =VLOOKUP($K8,$U$6:$AD$10,COLUMNS($L$7:L8)+1,FALSE) -> Bosnien | M8: =VLOOKUP($K8,$U$6:$AD$10,COLUMNS($L$7:M8)+1,FALSE) -> 0 | N8: =VLOOKUP($K8,$U$6:$AD$10,COLUMNS($L$7:N8)+1,FALSE) -> 0 | O8: =VLOOKUP($K8,$U$6:$AD$10,COLUMNS($L$7:O8)+1,FALSE) -> 0 | P8: =VLOOKUP($K8,$U$6:$AD$10,COLUMNS($L$7:P8)+1,FALSE) -> 0 | Q8: =VLOOKUP($K8,$U$6:$AD$10,COLUMNS($L$7:Q8)+1,FALSE) -> 0 | R8: =VLOOKUP($K8,$U$6:$AD$10,COLUMNS($L$7:R8)+1,FALSE) -> 0 | S8: =VLOOKUP($K8,$U$6:$AD$10,COLUMNS($L$7:S8)+1,FALSE) -> 0 | T8: =VLOOKUP($K8,$U$6:$AD$10,COLUMNS($L$7:T8)+1,FALSE) -> 0 | U8: =RANK(AE8,$AE$7:$AE$10,0)+COUNTIF($AE$6:AE7,AE8) -> 2 | V8: =+AG7 -> Bosnien | W8: =COUNTIFS($B$5:$B$10,V8,$C$5:$C$10,">=0")+COUNTIFS($E$5:$E$10,V8,$D$5:$D$10,">=0") -> 0 | X8: =COUNTIFS($B$5:$B$10,V8,$G$5:$G$10,3)+COUNTIFS($E$5:$E$10,V8,$H$5:$H$10,3) -> 0 | Y8: =COUNTIFS($B$5:$B$10,V8,$G$5:$G$10,1)+COUNTIFS($E$5:$E$10,V8,$H$5:$H$10,1) -> 0 | Z8: =COUNTIFS($B$5:$B$10,V8,$G$5:$G$10,0)+COUNTIFS($E$5:$E$10,V8,$H$5:$H$10,0) -> 0 | AA8: =SUMIF($B$5:$B$10,V8,$C$5:$C$10)+SUMIF($E$5:$E$10,V8,$D$5:$D$10) -> 0 | AB8: =SUMIF($B$5:$B$10,V8,$D$5:$D$10)+SUMIF($E$5:$E$10,V8,$C$5:$C$10) -> 0 | AC8: =+AA8-AB8 -> 0 | AD8: =SUMIF($B$5:$B$10,V8,$G$5:$G$10)+SUMIF($E$5:$E$10,V8,$H$5:$H$10) -> 0 | AE8: =SUM(AD8*1000000+AC8*10000+AA8*100+X8*10) -> 0 | AG8: ='VM-tipset 2026 mall'!BP83 -> Qatar
B9: ='VM-tipset 2026 mall'!B26 -> Kanada | C9: ='VM-tipset 2026 mall'!C26 | D9: ='VM-tipset 2026 mall'!E26 | E9: ='VM-tipset 2026 mall'!F26 -> Schweiz | G9: =IF(C9="","",IF(C9>D9,3,IF(C9=D9,1,0))) | H9: =IF(D9="","",IF(D9>C9,3,IF(D9=C9,1,0))) | K9: 3 | L9: =VLOOKUP($K9,$U$6:$AD$10,COLUMNS($L$7:L9)+1,FALSE) -> Qatar | M9: =VLOOKUP($K9,$U$6:$AD$10,COLUMNS($L$7:M9)+1,FALSE) -> 0 | N9: =VLOOKUP($K9,$U$6:$AD$10,COLUMNS($L$7:N9)+1,FALSE) -> 0 | O9: =VLOOKUP($K9,$U$6:$AD$10,COLUMNS($L$7:O9)+1,FALSE) -> 0 | P9: =VLOOKUP($K9,$U$6:$AD$10,COLUMNS($L$7:P9)+1,FALSE) -> 0 | Q9: =VLOOKUP($K9,$U$6:$AD$10,COLUMNS($L$7:Q9)+1,FALSE) -> 0 | R9: =VLOOKUP($K9,$U$6:$AD$10,COLUMNS($L$7:R9)+1,FALSE) -> 0 | S9: =VLOOKUP($K9,$U$6:$AD$10,COLUMNS($L$7:S9)+1,FALSE) -> 0 | T9: =VLOOKUP($K9,$U$6:$AD$10,COLUMNS($L$7:T9)+1,FALSE) -> 0 | U9: =RANK(AE9,$AE$7:$AE$10,0)+COUNTIF($AE$6:AE8,AE9) -> 3 | V9: =+AG8 -> Qatar | W9: =COUNTIFS($B$5:$B$10,V9,$C$5:$C$10,">=0")+COUNTIFS($E$5:$E$10,V9,$D$5:$D$10,">=0") -> 0 | X9: =COUNTIFS($B$5:$B$10,V9,$G$5:$G$10,3)+COUNTIFS($E$5:$E$10,V9,$H$5:$H$10,3) -> 0 | Y9: =COUNTIFS($B$5:$B$10,V9,$G$5:$G$10,1)+COUNTIFS($E$5:$E$10,V9,$H$5:$H$10,1) -> 0 | Z9: =COUNTIFS($B$5:$B$10,V9,$G$5:$G$10,0)+COUNTIFS($E$5:$E$10,V9,$H$5:$H$10,0) -> 0 | AA9: =SUMIF($B$5:$B$10,V9,$C$5:$C$10)+SUMIF($E$5:$E$10,V9,$D$5:$D$10) -> 0 | AB9: =SUMIF($B$5:$B$10,V9,$D$5:$D$10)+SUMIF($E$5:$E$10,V9,$C$5:$C$10) -> 0 | AC9: =+AA9-AB9 -> 0 | AD9: =SUMIF($B$5:$B$10,V9,$G$5:$G$10)+SUMIF($E$5:$E$10,V9,$H$5:$H$10) -> 0 | AE9: =SUM(AD9*1000000+AC9*10000+AA9*100+X9*10) -> 0 | AG9: ='VM-tipset 2026 mall'!BP84 -> Schweiz
B10: ='VM-tipset 2026 mall'!B27 -> Bosnien | C10: ='VM-tipset 2026 mall'!C27 | D10: ='VM-tipset 2026 mall'!E27 | E10: ='VM-tipset 2026 mall'!F27 -> Qatar | G10: =IF(C10="","",IF(C10>D10,3,IF(C10=D10,1,0))) | H10: =IF(D10="","",IF(D10>C10,3,IF(D10=C10,1,0))) | K10: 4 | L10: =VLOOKUP($K10,$U$6:$AD$10,COLUMNS($L$7:L10)+1,FALSE) -> Schweiz | M10: =VLOOKUP($K10,$U$6:$AD$10,COLUMNS($L$7:M10)+1,FALSE) -> 0 | N10: =VLOOKUP($K10,$U$6:$AD$10,COLUMNS($L$7:N10)+1,FALSE) -> 0 | O10: =VLOOKUP($K10,$U$6:$AD$10,COLUMNS($L$7:O10)+1,FALSE) -> 0 | P10: =VLOOKUP($K10,$U$6:$AD$10,COLUMNS($L$7:P10)+1,FALSE) -> 0 | Q10: =VLOOKUP($K10,$U$6:$AD$10,COLUMNS($L$7:Q10)+1,FALSE) -> 0 | R10: =VLOOKUP($K10,$U$6:$AD$10,COLUMNS($L$7:R10)+1,FALSE) -> 0 | S10: =VLOOKUP($K10,$U$6:$AD$10,COLUMNS($L$7:S10)+1,FALSE) -> 0 | T10: =VLOOKUP($K10,$U$6:$AD$10,COLUMNS($L$7:T10)+1,FALSE) -> 0 | U10: =RANK(AE10,$AE$7:$AE$10,0)+COUNTIF($AE$6:AE9,AE10) -> 4 | V10: =+AG9 -> Schweiz | W10: =COUNTIFS($B$5:$B$10,V10,$C$5:$C$10,">=0")+COUNTIFS($E$5:$E$10,V10,$D$5:$D$10,">=0") -> 0 | X10: =COUNTIFS($B$5:$B$10,V10,$G$5:$G$10,3)+COUNTIFS($E$5:$E$10,V10,$H$5:$H$10,3) -> 0 | Y10: =COUNTIFS($B$5:$B$10,V10,$G$5:$G$10,1)+COUNTIFS($E$5:$E$10,V10,$H$5:$H$10,1) -> 0 | Z10: =COUNTIFS($B$5:$B$10,V10,$G$5:$G$10,0)+COUNTIFS($E$5:$E$10,V10,$H$5:$H$10,0) -> 0 | AA10: =SUMIF($B$5:$B$10,V10,$C$5:$C$10)+SUMIF($E$5:$E$10,V10,$D$5:$D$10) -> 0 | AB10: =SUMIF($B$5:$B$10,V10,$D$5:$D$10)+SUMIF($E$5:$E$10,V10,$C$5:$C$10) -> 0 | AC10: =+AA10-AB10 -> 0 | AD10: =SUMIF($B$5:$B$10,V10,$G$5:$G$10)+SUMIF($E$5:$E$10,V10,$H$5:$H$10) -> 0 | AE10: =SUM(AD10*1000000+AC10*10000+AA10*100+X10*10) -> 0

Sheet Grupp C
B2: Grupp C
B4: Lag | G4: Poäng
B5: ='VM-tipset 2026 mall'!B30 -> Brasilien | C5: ='VM-tipset 2026 mall'!C30 | D5: ='VM-tipset 2026 mall'!E30 | E5: ='VM-tipset 2026 mall'!F30 -> Marocko | G5: =IF(C5="","",IF(C5>D5,3,IF(C5=D5,1,0))) | H5: =IF(D5="","",IF(D5>C5,3,IF(D5=C5,1,0))) | AG5: Grupp C
B6: ='VM-tipset 2026 mall'!B31 -> Haiti | C6: ='VM-tipset 2026 mall'!C31 | D6: ='VM-tipset 2026 mall'!E31 | E6: ='VM-tipset 2026 mall'!F31 -> Skottland | G6: =IF(C6="","",IF(C6>D6,3,IF(C6=D6,1,0))) | H6: =IF(D6="","",IF(D6>C6,3,IF(D6=C6,1,0))) | K6: Nn | L6: Teams | M6: P | N6: W | O6: D | P6: L | Q6: Ga | R6: Gf | S6: G+/- | T6: Points | U6: rank | V6: Teams | W6: P | X6: W | Y6: D | Z6: L | AA6: Ga | AB6: Gf | AC6: G+/- | AD6: Points | AE6: Criteria for rank | AG6: ='VM-tipset 2026 mall'!BP86 -> Brasilien
B7: ='VM-tipset 2026 mall'!B32 -> Brasilien | C7: ='VM-tipset 2026 mall'!C32 | D7: ='VM-tipset 2026 mall'!E32 | E7: ='VM-tipset 2026 mall'!F32 -> Haiti | G7: =IF(C7="","",IF(C7>D7,3,IF(C7=D7,1,0))) | H7: =IF(D7="","",IF(D7>C7,3,IF(D7=C7,1,0))) | K7: 1 | L7: =VLOOKUP($K7,$U$6:$AD$10,COLUMNS($L$7:L7)+1,FALSE) -> Brasilien | M7: =VLOOKUP($K7,$U$6:$AD$10,COLUMNS($L$7:M7)+1,FALSE) -> 0 | N7: =VLOOKUP($K7,$U$6:$AD$10,COLUMNS($L$7:N7)+1,FALSE) -> 0 | O7: =VLOOKUP($K7,$U$6:$AD$10,COLUMNS($L$7:O7)+1,FALSE) -> 0 | P7: =VLOOKUP($K7,$U$6:$AD$10,COLUMNS($L$7:P7)+1,FALSE) -> 0 | Q7: =VLOOKUP($K7,$U$6:$AD$10,COLUMNS($L$7:Q7)+1,FALSE) -> 0 | R7: =VLOOKUP($K7,$U$6:$AD$10,COLUMNS($L$7:R7)+1,FALSE) -> 0 | S7: =VLOOKUP($K7,$U$6:$AD$10,COLUMNS($L$7:S7)+1,FALSE) -> 0 | T7: =VLOOKUP($K7,$U$6:$AD$10,COLUMNS($L$7:T7)+1,FALSE) -> 0 | U7: =RANK(AE7,$AE$7:$AE$10,0)+COUNTIF($AE$6:AE6,AE7) -> 1 | V7: =+AG6 -> Brasilien | W7: =COUNTIFS($B$5:$B$10,V7,$C$5:$C$10,">=0")+COUNTIFS($E$5:$E$10,V7,$D$5:$D$10,">=0") -> 0 | X7: =COUNTIFS($B$5:$B$10,V7,$G$5:$G$10,3)+COUNTIFS($E$5:$E$10,V7,$H$5:$H$10,3) -> 0 | Y7: =COUNTIFS($B$5:$B$10,V7,$G$5:$G$10,1)+COUNTIFS($E$5:$E$10,V7,$H$5:$H$10,1) -> 0 | Z7: =COUNTIFS($B$5:$B$10,V7,$G$5:$G$10,0)+COUNTIFS($E$5:$E$10,V7,$H$5:$H$10,0) -> 0 | AA7: =SUMIF($B$5:$B$10,V7,$C$5:$C$10)+SUMIF($E$5:$E$10,V7,$D$5:$D$10) -> 0 | AB7: =SUMIF($B$5:$B$10,V7,$D$5:$D$10)+SUMIF($E$5:$E$10,V7,$C$5:$C$10) -> 0 | AC7: =+AA7-AB7 -> 0 | AD7: =SUMIF($B$5:$B$10,V7,$G$5:$G$10)+SUMIF($E$5:$E$10,V7,$H$5:$H$10) -> 0 | AE7: =SUM(AD7*1000000+AC7*10000+AA7*100+X7*10) -> 0 | AG7: ='VM-tipset 2026 mall'!BP87 -> Marocko
B8: ='VM-tipset 2026 mall'!B33 -> Marocko | C8: ='VM-tipset 2026 mall'!C33 | D8: ='VM-tipset 2026 mall'!E33 | E8: ='VM-tipset 2026 mall'!F33 -> Skottland | G8: =IF(C8="","",IF(C8>D8,3,IF(C8=D8,1,0))) | H8: =IF(D8="","",IF(D8>C8,3,IF(D8=C8,1,0))) | K8: 2 | L8: =VLOOKUP($K8,$U$6:$AD$10,COLUMNS($L$7:L8)+1,FALSE) -> Marocko | M8: =VLOOKUP($K8,$U$6:$AD$10,COLUMNS($L$7:M8)+1,FALSE) -> 0 | N8: =VLOOKUP($K8,$U$6:$AD$10,COLUMNS($L$7:N8)+1,FALSE) -> 0 | O8: =VLOOKUP($K8,$U$6:$AD$10,COLUMNS($L$7:O8)+1,FALSE) -> 0 | P8: =VLOOKUP($K8,$U$6:$AD$10,COLUMNS($L$7:P8)+1,FALSE) -> 0 | Q8: =VLOOKUP($K8,$U$6:$AD$10,COLUMNS($L$7:Q8)+1,FALSE) -> 0 | R8: =VLOOKUP($K8,$U$6:$AD$10,COLUMNS($L$7:R8)+1,FALSE) -> 0 | S8: =VLOOKUP($K8,$U$6:$AD$10,COLUMNS($L$7:S8)+1,FALSE) -> 0 | T8: =VLOOKUP($K8,$U$6:$AD$10,COLUMNS($L$7:T8)+1,FALSE) -> 0 | U8: =RANK(AE8,$AE$7:$AE$10,0)+COUNTIF($AE$6:AE7,AE8) -> 2 | V8: =+AG7 -> Marocko | W8: =COUNTIFS($B$5:$B$10,V8,$C$5:$C$10,">=0")+COUNTIFS($E$5:$E$10,V8,$D$5:$D$10,">=0") -> 0 | X8: =COUNTIFS($B$5:$B$10,V8,$G$5:$G$10,3)+COUNTIFS($E$5:$E$10,V8,$H$5:$H$10,3) -> 0 | Y8: =COUNTIFS($B$5:$B$10,V8,$G$5:$G$10,1)+COUNTIFS($E$5:$E$10,V8,$H$5:$H$10,1) -> 0 | Z8: =COUNTIFS($B$5:$B$10,V8,$G$5:$G$10,0)+COUNTIFS($E$5:$E$10,V8,$H$5:$H$10,0) -> 0 | AA8: =SUMIF($B$5:$B$10,V8,$C$5:$C$10)+SUMIF($E$5:$E$10,V8,$D$5:$D$10) -> 0 | AB8: =SUMIF($B$5:$B$10,V8,$D$5:$D$10)+SUMIF($E$5:$E$10,V8,$C$5:$C$10) -> 0 | AC8: =+AA8-AB8 -> 0 | AD8: =SUMIF($B$5:$B$10,V8,$G$5:$G$10)+SUMIF($E$5:$E$10,V8,$H$5:$H$10) -> 0 | AE8: =SUM(AD8*1000000+AC8*10000+AA8*100+X8*10) -> 0 | AG8: ='VM-tipset 2026 mall'!BP88 -> Haiti
B9: ='VM-tipset 2026 mall'!B34 -> Brasilien | C9: ='VM-tipset 2026 mall'!C34 | D9: ='VM-tipset 2026 mall'!E34 | E9: ='VM-tipset 2026 mall'!F34 -> Skottland | G9: =IF(C9="","",IF(C9>D9,3,IF(C9=D9,1,0))) | H9: =IF(D9="","",IF(D9>C9,3,IF(D9=C9,1,0))) | K9: 3 | L9: =VLOOKUP($K9,$U$6:$AD$10,COLUMNS($L$7:L9)+1,FALSE) -> Haiti | M9: =VLOOKUP($K9,$U$6:$AD$10,COLUMNS($L$7:M9)+1,FALSE) -> 0 | N9: =VLOOKUP($K9,$U$6:$AD$10,COLUMNS($L$7:N9)+1,FALSE) -> 0 | O9: =VLOOKUP($K9,$U$6:$AD$10,COLUMNS($L$7:O9)+1,FALSE) -> 0 | P9: =VLOOKUP($K9,$U$6:$AD$10,COLUMNS($L$7:P9)+1,FALSE) -> 0 | Q9: =VLOOKUP($K9,$U$6:$AD$10,COLUMNS($L$7:Q9)+1,FALSE) -> 0 | R9: =VLOOKUP($K9,$U$6:$AD$10,COLUMNS($L$7:R9)+1,FALSE) -> 0 | S9: =VLOOKUP($K9,$U$6:$AD$10,COLUMNS($L$7:S9)+1,FALSE) -> 0 | T9: =VLOOKUP($K9,$U$6:$AD$10,COLUMNS($L$7:T9)+1,FALSE) -> 0 | U9: =RANK(AE9,$AE$7:$AE$10,0)+COUNTIF($AE$6:AE8,AE9) -> 3 | V9: =+AG8 -> Haiti | W9: =COUNTIFS($B$5:$B$10,V9,$C$5:$C$10,">=0")+COUNTIFS($E$5:$E$10,V9,$D$5:$D$10,">=0") -> 0 | X9: =COUNTIFS($B$5:$B$10,V9,$G$5:$G$10,3)+COUNTIFS($E$5:$E$10,V9,$H$5:$H$10,3) -> 0 | Y9: =COUNTIFS($B$5:$B$10,V9,$G$5:$G$10,1)+COUNTIFS($E$5:$E$10,V9,$H$5:$H$10,1) -> 0 | Z9: =COUNTIFS($B$5:$B$10,V9,$G$5:$G$10,0)+COUNTIFS($E$5:$E$10,V9,$H$5:$H$10,0) -> 0 | AA9: =SUMIF($B$5:$B$10,V9,$C$5:$C$10)+SUMIF($E$5:$E$10,V9,$D$5:$D$10) -> 0 | AB9: =SUMIF($B$5:$B$10,V9,$D$5:$D$10)+SUMIF($E$5:$E$10,V9,$C$5:$C$10) -> 0 | AC9: =+AA9-AB9 -> 0 | AD9: =SUMIF($B$5:$B$10,V9,$G$5:$G$10)+SUMIF($E$5:$E$10,V9,$H$5:$H$10) -> 0 | AE9: =SUM(AD9*1000000+AC9*10000+AA9*100+X9*10) -> 0 | AG9: ='VM-tipset 2026 mall'!BP89 -> Skottland
B10: ='VM-tipset 2026 mall'!B35 -> Marocko | C10: ='VM-tipset 2026 mall'!C35 | D10: ='VM-tipset 2026 mall'!E35 | E10: ='VM-tipset 2026 mall'!F35 -> Haiti | G10: =IF(C10="","",IF(C10>D10,3,IF(C10=D10,1,0))) | H10: =IF(D10="","",IF(D10>C10,3,IF(D10=C10,1,0))) | K10: 4 | L10: =VLOOKUP($K10,$U$6:$AD$10,COLUMNS($L$7:L10)+1,FALSE) -> Skottland | M10: =VLOOKUP($K10,$U$6:$AD$10,COLUMNS($L$7:M10)+1,FALSE) -> 0 | N10: =VLOOKUP($K10,$U$6:$AD$10,COLUMNS($L$7:N10)+1,FALSE) -> 0 | O10: =VLOOKUP($K10,$U$6:$AD$10,COLUMNS($L$7:O10)+1,FALSE) -> 0 | P10: =VLOOKUP($K10,$U$6:$AD$10,COLUMNS($L$7:P10)+1,FALSE) -> 0 | Q10: =VLOOKUP($K10,$U$6:$AD$10,COLUMNS($L$7:Q10)+1,FALSE) -> 0 | R10: =VLOOKUP($K10,$U$6:$AD$10,COLUMNS($L$7:R10)+1,FALSE) -> 0 | S10: =VLOOKUP($K10,$U$6:$AD$10,COLUMNS($L$7:S10)+1,FALSE) -> 0 | T10: =VLOOKUP($K10,$U$6:$AD$10,COLUMNS($L$7:T10)+1,FALSE) -> 0 | U10: =RANK(AE10,$AE$7:$AE$10,0)+COUNTIF($AE$6:AE9,AE10) -> 4 | V10: =+AG9 -> Skottland | W10: =COUNTIFS($B$5:$B$10,V10,$C$5:$C$10,">=0")+COUNTIFS($E$5:$E$10,V10,$D$5:$D$10,">=0") -> 0 | X10: =COUNTIFS($B$5:$B$10,V10,$G$5:$G$10,3)+COUNTIFS($E$5:$E$10,V10,$H$5:$H$10,3) -> 0 | Y10: =COUNTIFS($B$5:$B$10,V10,$G$5:$G$10,1)+COUNTIFS($E$5:$E$10,V10,$H$5:$H$10,1) -> 0 | Z10: =COUNTIFS($B$5:$B$10,V10,$G$5:$G$10,0)+COUNTIFS($E$5:$E$10,V10,$H$5:$H$10,0) -> 0 | AA10: =SUMIF($B$5:$B$10,V10,$C$5:$C$10)+SUMIF($E$5:$E$10,V10,$D$5:$D$10) -> 0 | AB10: =SUMIF($B$5:$B$10,V10,$D$5:$D$10)+SUMIF($E$5:$E$10,V10,$C$5:$C$10) -> 0 | AC10: =+AA10-AB10 -> 0 | AD10: =SUMIF($B$5:$B$10,V10,$G$5:$G$10)+SUMIF($E$5:$E$10,V10,$H$5:$H$10) -> 0 | AE10: =SUM(AD10*1000000+AC10*10000+AA10*100+X10*10) -> 0

Sheet Grupp D
B2: Grupp D
B4: Lag | G4: Poäng
B5: ='VM-tipset 2026 mall'!B38 -> USA | C5: ='VM-tipset 2026 mall'!C38 | D5: ='VM-tipset 2026 mall'!E38 | E5: ='VM-tipset 2026 mall'!F38 -> Paraguay | G5: =IF(C5="","",IF(C5>D5,3,IF(C5=D5,1,0))) | H5: =IF(D5="","",IF(D5>C5,3,IF(D5=C5,1,0))) | AG5: Grupp D
B6: ='VM-tipset 2026 mall'!B39 -> Australien | C6: ='VM-tipset 2026 mall'!C39 | D6: ='VM-tipset 2026 mall'!E39 | E6: ='VM-tipset 2026 mall'!F39 -> Turkiet | G6: =IF(C6="","",IF(C6>D6,3,IF(C6=D6,1,0))) | H6: =IF(D6="","",IF(D6>C6,3,IF(D6=C6,1,0))) | K6: Nn | L6: Teams | M6: P | N6: W | O6: D | P6: L | Q6: Ga | R6: Gf | S6: G+/- | T6: Points | U6: rank | V6: Teams | W6: P | X6: W | Y6: D | Z6: L | AA6: Ga | AB6: Gf | AC6: G+/- | AD6: Points | AE6: Criteria for rank | AG6: ='VM-tipset 2026 mall'!BP91 -> USA
